<?xml version="1.0"?>

<robot xmlns:xacro="http://ros.org/wiki/xacro">

    <author>Rein Appeldoorn</author>
    <review status="unreviewed" notes=""/>

    <joint name="base_phi_joint" type="continuous">
        <axis xyz="0 0 1"/>
        <parent link="base_y_link"/>
        <origin rpy="0 0 0" xyz="0 0 0"/>
        <child link="base_link"/>
        <dynamics damping="100" friction="20" />
	<limit effort="1000" velocity="1000" lower="-1000" upper="1000" />
    </joint> 

    <link name="base_y_link">
        <inertial>
            <mass value="10"/>
            <origin xyz="0 0 0"/>
            <inertia ixx="0.1" ixy="0.1" ixz="0.1" iyy="0.1" iyz="0.1" izz="0.1"/>
        </inertial>
    </link>

    <joint name="base_y_joint" type="prismatic">
        <axis xyz="0 1 0" />
        <parent link="base_x_link" />
        <origin rpy="0 0 0" xyz="0 0 0" />
        <child link="base_y_link" />
        <dynamics damping="100" friction="20" />
        <limit effort="1000" velocity="1000" lower="-1000" upper="1000" />
    </joint>

    <link name="base_x_link">
        <inertial>
            <mass value="10"/>
            <origin xyz="0 0 0"/>
            <inertia ixx="0.1" ixy="0.1" ixz="0.1" iyy="0.1" iyz="0.1" izz="0.1"/>
        </inertial>
    </link>

    <joint name="base_x_joint" type="prismatic">
        <axis xyz="1 0 0" />
        <parent link="base_fixed_link" />
        <origin rpy="0 0 0" xyz="0 0 0" />
        <child link="base_x_link" />
        <dynamics damping="100" friction="20" />
	<limit effort="1000" velocity="1000" lower="-1000" upper="1000" />
    </joint>

    <link name="base_fixed_link">
        <inertial>
            <mass value="10"/>
            <origin xyz="0 0 0"/>
            <inertia ixx="0.1" ixy="0.1" ixz="0.1" iyy="0.1" iyz="0.1" izz="0.1"/>
        </inertial>
    </link>

    <joint name="base_fixed_joint" type="fixed">
        <parent link="world" />
        <origin rpy="0 0 0" xyz="0 0 0" />
        <child link="base_fixed_link" />
    </joint>

    <link name="world" />

</robot>
