<?xml version="1.0"?>

<robot xmlns:xacro="http://ros.org/wiki/xacro">

   <author>Kris van Tienhoven</author>
   <license>BSD</license>
   <review status="unreviewed" notes=""/>

<!--Start of the macro for the four cylinders that are the wheels
@param side_LR is "left"  or "right"
@param side_FR is "front" or "rear"
@param sign_LR is - or +
@param sign_FR is - or +
@param wheel_angle is the initial rotation of the wheel -->
<xacro:macro name="wheel" params="side_LR side_FR sign_LR sign_FR wheel_angle">
  
  <joint name="wheel_inner_joint_${side_LR}_${side_FR}" type="continuous">
    <parent link="base"/>
    <child link="wheel_${side_LR}_${side_FR}"/>
    <axis xyz="1 0 0"/>
    <origin xyz="${sign_LR}0.2 ${sign_FR}0.2 0.005" rpy="0 0 ${wheel_angle}"/>
    <dynamics damping="1" friction="0.0"/>
    <limit effort="5.0" velocity="5.0"/>
  </joint>

  <xacro:my_link name="wheel_${side_LR}_${side_FR}" mass="0.5" color="Grey">
    <cylinder radius="0.05" length="0.05"/>
    <origin xyz="0.0 0.0 0.0" rpy="0 0 0"/>
    <origin xyz="0.0 0.0 0.0" rpy="0 1.5708 0" />
    <inertia ixx="0.0006"  ixy="0"  ixz="0" iyy="0.0006" iyz="0" izz="0.0006" />
   </xacro:my_link>
   
</xacro:macro>

<!--Start of the macro for the 12 spheres on each wheel
@param side_LR is "left"  or "right"
@param side_FR is "front" or "rear"
@param number is a integer out of the interval [1...12]
@param y_ is the y position of the sphere
@param z_ is the z position of the wheel
@param roll_ is the initial rotation of the sphere -->
<xacro:macro name="z_sphere" params="side_LR side_FR number y_ z_ roll_">

	<joint name="omni_sphere${number}_joint_${side_LR}_${side_FR}" type="continuous">
		<parent link="wheel_${side_LR}_${side_FR}"/>
		<child link="omni_sphere${number}_${side_LR}_${side_FR}"/>
		<axis xyz="0 1 0"/>
		<origin xyz="0.0 ${y_} ${z_}" rpy="${roll_} 0 0"/>
		<dynamics damping="0.01" friction="0.0"/>
		<limit effort="0.5" velocity="0.05"/>
	</joint>

	<xacro:my_link name="omni_sphere${number}_${side_LR}_${side_FR}" mass="0.05" color="Grey">
		<sphere radius="0.03" />
		<origin xyz="0.0 0.0 0.0" rpy="0 0 0"/>
		<origin xyz="0.0 0.0 0.0" rpy="0 0 0" />
		<inertia ixx="0.000018"  ixy="0"  ixz="0" iyy="0.000018" iyz="0" izz="0.000018" />
	</xacro:my_link>
	
</xacro:macro>

<!--the macro that calls the macro for a sphere for each wheel
@param nr is a integer out of the interval [1...12]
@param y is the y position of the sphere
@param z is the z position of the wheel
@param roll is the initial rotation of the sphere -->
<xacro:macro name="spheres" params="nr y z roll">
  <xacro:z_sphere side_LR="left" side_FR="front" number="${nr}" y_="${y}" z_="${z}" roll_="${roll}"/>
  <xacro:z_sphere side_LR="right" side_FR="front"  number="${nr}" y_="${y}" z_="${z}" roll_="${roll}"/>
  <xacro:z_sphere side_LR="left" side_FR="rear" number="${nr}" y_="${y}" z_="${z}" roll_="${roll}"/>
  <xacro:z_sphere side_LR="right" side_FR="rear" number="${nr}" y_="${y}" z_="${z}" roll_="${roll}"/>
</xacro:macro>

<!--calling the macro to create a sphere for each wheel 12 times-->
<xacro:spheres nr="1" y="0.03" z="0.0" roll="0.0"/>
<xacro:spheres nr="2" y="0.026" z="0.015" roll="0.5236"/>
<xacro:spheres nr="3" y="0.015" z="0.026" roll="1.0472"/>
<xacro:spheres nr="4" y="0" z="0.03" roll="1.5708"/>
<xacro:spheres nr="5" y="-0.015" z="0.026" roll="2.0944"/>
<xacro:spheres nr="6" y="-0.026" z="0.015" roll="2.6180"/>

<xacro:spheres nr="7" y="-0.03" z="0.0" roll="3.1416"/>
<xacro:spheres nr="8" y="-0.026" z="-0.015" roll="3.6652"/>
<xacro:spheres nr="9" y="-0.015" z="-0.026" roll="4.1888"/>
<xacro:spheres nr="10" y="0.0" z="-0.03" roll="4.7124"/>
<xacro:spheres nr="11" y="0.015" z="-0.026" roll="5.2360"/>
<xacro:spheres nr="12" y="0.026" z="-0.015" roll="5.7596"/>

</robot>

