<?xml version="1.0" ?>
<!-- =================================================================================== -->
<!-- |    This document was autogenerated by xacro from /home/sdries/ros/groovy/tue/trunk/amigo_common/amigo_description/scripts/../urdf/xacro/amigo_old.urdf.xacro | -->
<!-- |    EDITING THIS FILE BY HAND IS NOT RECOMMENDED                                 | -->
<!-- =================================================================================== -->
<robot name="amigo" xmlns:controller="http://playerstage.sourceforge.net/gazebo/xmlschema/#controller" xmlns:interface="http://playerstage.sourceforge.net/gazebo/xmlschema/#interface" xmlns:sensor="http://playerstage.sourceforge.net/gazebo/xmlschema/#sensor" xmlns:xacro="http://ros.org/wiki/xacro">
  <author>Rob Janssen</author>
  <license>BSD</license>
  <review notes="" status="unreviewed"/>
  <!--get link & joint definitions -->
  <author>Kris van Tienhoven</author>
  <license>BSD</license>
  <review notes="" status="unreviewed"/>
  <!--get custom materials -->
  <author>Kris van Tienhoven</author>
  <license>BSD</license>
  <review notes="" status="unreviewed"/>
  <material name="Blue">
    <color rgba="0.0 0.0 0.8 1.0"/>
  </material>
  <material name="Green">
    <color rgba="0.0 0.8 0.0 1.0"/>
  </material>
  <material name="Grey">
    <color rgba="0.7 0.7 0.7 1.0"/>
  </material>
  <material name="Grey2">
    <color rgba="0.9 0.9 0.9 1.0"/>
  </material>
  <material name="Red">
    <color rgba="0.8 0.0 0.0 1.0"/>
  </material>
  <material name="White">
    <color rgba="1.0 1.0 1.0 1.0"/>
  </material>
  <material name="Black">
    <color rgba="0.1 0.1 0.1 1.0"/>
  </material>
  <material name="LightGrey">
    <color rgba="0.6 0.6 0.6 1.0"/>
  </material>
  <material name="amigo_description/bottomcovers">
    <texture filename="package://amigo_description/media/materials/textures/bottomcovers/finalreduced.jpg"/>
  </material>
  <material name="amigo_description/white">
    <texture filename="package://amigo_description/media/materials/textures/white/white.jpg"/>
  </material>
  <material name="amigo_description/logo">
    <texture filename="package://amigo_description/media/materials/textures/logo/tue.jpg"/>
  </material>
  <material name="amigo_description/aluminium">
    <texture filename="package://amigo_description/media/materials/textures/aluminium/aluminium_0001_c.jpg"/>
  </material>
  <material name="amigo_description/orange">
    <texture filename="package://amigo_description/media/materials/textures/orange/orange.jpg"/>
  </material>
  <!--========BUILD BODY======-->
  <author>Rob Janssen, Kris van Tienhoven</author>
  <license>BSD</license>
  <review notes="" status="unreviewed"/>
  <link name="torso">
    <inertial>
      <origin rpy="0 0 0" xyz="0.0 0.0 0.0"/>
      <mass value="16"/>
      <inertia ixx="0.01" ixy="0" ixz="0" iyy="0.01" iyz="0" izz="0.01"/>
    </inertial>
    <visual>
      <origin rpy="-1.5708 0 -1.5708" xyz="0.045 0.0 0.06"/>
      <geometry>
        <mesh filename="package://amigo_description/media/meshes/torsocovers.dae" scale="0.0004 0.0004 0.0004"/>
      </geometry>
      <material name="amigo_description/white"/>
    </visual>
    <collision>
      <origin rpy="-1.5708 0 -1.5708" xyz="0.045 0.0 0.06"/>
      <geometry>
        <mesh filename="package://amigo_description/media/meshes/torsocovers.dae" scale="0.0004 0.0004 0.0004"/>
      </geometry>
    </collision>
  </link>
  <gazebo reference="torso">
    <material>amigo_description/white</material>
    <turnGravityOff>false</turnGravityOff>
  </gazebo>
  <link name="torso_slider">
    <inertial>
      <origin rpy="0 0 0" xyz="0 0 0"/>
      <mass value="0.1"/>
      <inertia ixx="0.01" ixy="0" ixz="0" iyy="0.01" iyz="0" izz="0.01"/>
    </inertial>
    <visual>
      <origin rpy="0 0 1.5708" xyz="0.05 0 0.0"/>
      <geometry>
        <mesh filename="package://amigo_description/media/meshes/torsoslidertextured.dae" scale="0.004 0.004 0.004"/>
      </geometry>
      <material name="amigo_description/aluminium"/>
    </visual>
    <collision>
      <origin rpy="0 0 1.5708" xyz="0.05 0 0.0"/>
      <geometry>
        <mesh filename="package://amigo_description/media/meshes/torsoslidertextured.dae" scale="0.004 0.004 0.004"/>
      </geometry>
    </collision>
  </link>
  <gazebo reference="torso_slider">
    <material>amigo_description/aluminium</material>
    <turnGravityOff>false</turnGravityOff>
  </gazebo>
  <link name="base">
    <inertial>
      <origin rpy="0 0 0" xyz="0.0 0.0 0.3275"/>
      <mass value="20"/>
      <inertia ixx="2.63" ixy="0" ixz="0" iyy="2.63" iyz="0" izz="2.4"/>
    </inertial>
    <visual>
      <origin rpy="0 0 -1.5708" xyz="0.0 0.0 0.23"/>
      <geometry>
        <mesh filename="package://amigo_description/media/meshes/bottomcovers.dae" scale="0.0004 0.0004 0.0004"/>
      </geometry>
      <material name="amigo_description/bottomcovers"/>
    </visual>
    <collision>
      <origin rpy="0 0 -1.5708" xyz="0.0 0.0 0.23"/>
      <geometry>
        <mesh filename="package://amigo_description/media/meshes/bottomcovers.dae" scale="0.0004 0.0004 0.0004"/>
      </geometry>
    </collision>
  </link>
  <gazebo reference="base">
    <material>amigo_description/bottomcovers</material>
    <turnGravityOff>false</turnGravityOff>
  </gazebo>
  <link name="base_link">
    <inertial>
      <origin rpy="0 0 0" xyz="0.0 0.0 0.0"/>
      <mass value="0"/>
      <inertia ixx="0" ixy="0" ixz="0" iyy="0" iyz="0" izz="0"/>
    </inertial>
    <visual>
      <origin rpy="0 0 0" xyz="0.0 0.0 0.0"/>
      <geometry>
        <cylinder length="0.00" radius="0.0"/>
      </geometry>
      <material name="Red">
     </material>
    </visual>
    <collision>
      <origin rpy="0 0 0" xyz="0.0 0.0 0.0"/>
      <geometry>
        <cylinder length="0.00" radius="0.0"/>
      </geometry>
    </collision>
  </link>
  <gazebo reference="base_link">
    <material>Gazebo/Red</material>
    <turnGravityOff>false</turnGravityOff>
  </gazebo>
  <joint name="torso_joint" type="prismatic">
    <parent link="base"/>
    <child link="torso_slider"/>
    <axis xyz="1 0 0"/>
    <origin rpy="3.14159265 -1.5708 0" xyz="0.0 0.0 0.58"/>
    <dynamics damping="3" friction="0.0"/>
    <!--*-->
    <limit effort="1000" lower="0.0" upper="0.41" velocity="10.0"/>
    <!--*-->
  </joint>
  <joint name="base_link_joint" type="fixed">
    <parent link="base_link"/>
    <child link="base"/>
    <axis xyz="1 0 0"/>
    <origin rpy="0 0 0" xyz="0.0 0.0 0.055"/>
  </joint>
  <joint name="torso_slider_joint" type="fixed">
    <parent link="torso_slider"/>
    <child link="torso"/>
    <axis xyz="1 0 0"/>
    <origin rpy="0 0 0" xyz="0.135 0.0 0.0"/>
  </joint>
  <!--extra body visuals-->
  <author>Kris van Tienhoven</author>
  <license>BSD</license>
  <review notes="" status="unreviewed"/>
  <link name="base_plate">
    <inertial>
      <origin rpy="0 0 0" xyz="0.0 0.0 0.0"/>
      <mass value="0.1"/>
      <inertia ixx="0.01" ixy="0" ixz="0" iyy="0.01" iyz="0" izz="0.01"/>
    </inertial>
    <visual>
      <origin rpy="0 0 0" xyz="0.0 0.0 0.0"/>
      <geometry>
        <cylinder length="0.02" radius="0.333"/>
      </geometry>
      <material name="amigo_description/aluminium">
     </material>
    </visual>
    <collision>
      <origin rpy="0 0 0" xyz="0.0 0.0 0.0"/>
      <geometry>
        <cylinder length="0.02" radius="0.333"/>
      </geometry>
    </collision>
  </link>
  <gazebo reference="base_plate">
    <material>amigo_description/aluminium</material>
    <turnGravityOff>false</turnGravityOff>
  </gazebo>
  <joint name="base_plate_joint" type="fixed">
    <parent link="base_link"/>
    <child link="base_plate"/>
    <axis xyz="1 0 0"/>
    <origin rpy="0 0 0" xyz="0.0 0.0 0.05"/>
  </joint>
  <link name="torso_assist_slider_right">
    <inertial>
      <origin rpy="0 0 0" xyz="0 0 0"/>
      <mass value="0.01"/>
      <inertia ixx="0.01" ixy="0" ixz="0" iyy="0.01" iyz="0" izz="0.01"/>
    </inertial>
    <visual>
      <origin rpy="0 1.5708 0" xyz="-0.4  0.0 0.0"/>
      <geometry>
        <mesh filename="package://amigo_description/media/meshes/torsoassistslidertextured.dae" scale="0.004 0.004 0.005"/>
      </geometry>
      <material name="amigo_description/aluminium"/>
    </visual>
    <collision>
      <origin rpy="0 1.5708 0" xyz="-0.4  0.0 0.0"/>
      <geometry>
        <mesh filename="package://amigo_description/media/meshes/torsoassistslidertextured.dae" scale="0.004 0.004 0.005"/>
      </geometry>
    </collision>
  </link>
  <gazebo reference="torso_assist_slider_right">
    <material>amigo_description/aluminium</material>
    <turnGravityOff>false</turnGravityOff>
  </gazebo>
  <link name="torso_assist_slider_left">
    <inertial>
      <origin rpy="0 0 0" xyz="0 0 0"/>
      <mass value="0.01"/>
      <inertia ixx="0.01" ixy="0" ixz="0" iyy="0.01" iyz="0" izz="0.01"/>
    </inertial>
    <visual>
      <origin rpy="0 1.5708 0" xyz="-0.4  0.0 0.0"/>
      <geometry>
        <mesh filename="package://amigo_description/media/meshes/torsoassistslidertextured.dae" scale="0.004 0.004 0.005"/>
      </geometry>
      <material name="amigo_description/aluminium"/>
    </visual>
    <collision>
      <origin rpy="0 1.5708 0" xyz="-0.4  0.0 0.0"/>
      <geometry>
        <mesh filename="package://amigo_description/media/meshes/torsoassistslidertextured.dae" scale="0.004 0.004 0.005"/>
      </geometry>
    </collision>
  </link>
  <gazebo reference="torso_assist_slider_left">
    <material>amigo_description/aluminium</material>
    <turnGravityOff>false</turnGravityOff>
  </gazebo>
  <link name="torso_assist_slider_back">
    <inertial>
      <origin rpy="0 0 0" xyz="0 0 0"/>
      <mass value="0.01"/>
      <inertia ixx="0.01" ixy="0" ixz="0" iyy="0.01" iyz="0" izz="0.01"/>
    </inertial>
    <visual>
      <origin rpy="0 1.5708 0" xyz="-0.4 0.0 0.0"/>
      <geometry>
        <mesh filename="package://amigo_description/media/meshes/torsoassistslidertextured.dae" scale="0.004 0.004 0.005"/>
      </geometry>
      <material name="amigo_description/aluminium"/>
    </visual>
    <collision>
      <origin rpy="0 1.5708 0" xyz="-0.4 0.0 0.0"/>
      <geometry>
        <mesh filename="package://amigo_description/media/meshes/torsoassistslidertextured.dae" scale="0.004 0.004 0.005"/>
      </geometry>
    </collision>
  </link>
  <gazebo reference="torso_assist_slider_back">
    <material>amigo_description/aluminium</material>
    <turnGravityOff>false</turnGravityOff>
  </gazebo>
  <joint name="torso_slider_assist_joint_right" type="fixed">
    <parent link="torso"/>
    <child link="torso_assist_slider_right"/>
    <origin rpy="0 0 0" xyz="-0.3 0.1 0.0"/>
  </joint>
  <joint name="torso_slider_assist_joint_left" type="fixed">
    <parent link="torso"/>
    <child link="torso_assist_slider_left"/>
    <origin rpy="0 0 0" xyz="-0.3 -0.1 0.0"/>
  </joint>
  <joint name="torso_slider_assist_joint_back" type="fixed">
    <parent link="torso"/>
    <child link="torso_assist_slider_back"/>
    <origin rpy="1.5708 0 0" xyz="-0.3 0.0 -0.1"/>
  </joint>
  <link name="clavicles">
    <inertial>
      <origin rpy="0 0 0" xyz="0 0 0"/>
      <mass value="0.01"/>
      <inertia ixx="0.01" ixy="0" ixz="0" iyy="0.01" iyz="0" izz="0.01"/>
    </inertial>
    <visual>
      <origin rpy="0 0 0" xyz="0.0 0.0 0.0"/>
      <geometry>
        <box size="0.1 0.436 0.11"/>
      </geometry>
      <material name="Black">
     </material>
    </visual>
    <collision>
      <origin rpy="0 0 0" xyz="0.0 0.0 0.0"/>
      <geometry>
        <box size="0.1 0.436 0.11"/>
      </geometry>
    </collision>
  </link>
  <gazebo reference="clavicles">
    <material>Gazebo/Black</material>
    <turnGravityOff>false</turnGravityOff>
  </gazebo>
  <joint name="clavicle_joint" type="fixed">
    <parent link="torso"/>
    <child link="clavicles"/>
    <origin rpy="0 0 0" xyz="0.05 0.0 0.0"/>
  </joint>
  <!--========BUILD LASERS======-->
  <author>Kris van Tienhoven</author>
  <license>BSD</license>
  <review notes="" status="unreviewed"/>
  <link name="base_laser">
    <inertial>
      <origin rpy="0 0 0" xyz="0.0 0.0 0.0"/>
      <mass value="0.5"/>
      <inertia ixx="0.0001" ixy="0" ixz="0" iyy="0.0001" iyz="0" izz="0.0001"/>
    </inertial>
    <visual>
      <origin rpy="0 0 0" xyz="-0.005 0.0 -0.065"/>
      <geometry>
        <box size="0.05 0.065 0.12"/>
      </geometry>
      <material name="Black">
     </material>
    </visual>
    <collision>
      <origin rpy="0 0 0" xyz="-0.005 0.0 -0.065"/>
      <geometry>
        <box size="0.05 0.065 0.12"/>
      </geometry>
    </collision>
  </link>
  <gazebo reference="base_laser">
    <material>Gazebo/Black</material>
    <turnGravityOff>false</turnGravityOff>
  </gazebo>
  <joint name="base_laser_joint" type="fixed">
    <parent link="base"/>
    <child link="base_laser"/>
    <origin rpy="0 0 0" xyz="0.31 0.0 0.185"/>
    <axis xyz="0 1 0"/>
    <dynamics damping="0.1" friction="0"/>
    <limit effort="13.4" lower="-0.7809" upper="1.5708" velocity="1.0"/>
  </joint>
  <link name="lasertop">
    <inertial>
      <origin rpy="0 0 0" xyz="0.0 0.0 0.0"/>
      <mass value="0.01"/>
      <inertia ixx="0.0001" ixy="0" ixz="0" iyy="0.0001" iyz="0" izz="0.0001"/>
    </inertial>
    <visual>
      <origin rpy="0 0 0" xyz="-0.005 0.0 0.0"/>
      <geometry>
        <box size="0.05 0.065 0.01"/>
      </geometry>
      <material name="amigo_description/orange">
     </material>
    </visual>
    <collision>
      <origin rpy="0 0 0" xyz="-0.005 0.0 0.0"/>
      <geometry>
        <box size="0.05 0.065 0.01"/>
      </geometry>
    </collision>
  </link>
  <gazebo reference="lasertop">
    <material>amigo_description/orange</material>
    <turnGravityOff>false</turnGravityOff>
  </gazebo>
  <joint name="lasertop_joint" type="fixed">
    <parent link="base_laser"/>
    <child link="lasertop"/>
  </joint>
  <link name="logo">
    <inertial>
      <origin rpy="0 0 0" xyz="0.0 0.0 0.0"/>
      <mass value="0.01"/>
      <inertia ixx="0.0001" ixy="0" ixz="0" iyy="0.0001" iyz="0" izz="0.0001"/>
    </inertial>
    <visual>
      <origin rpy="0 0 3.1415" xyz="0.025 0.0 -0.14"/>
      <geometry>
        <mesh filename="package://amigo_description/media/meshes/logo.dae" scale="0.0016 0.0016 0.0016"/>
      </geometry>
      <material name="amigo_description/logo"/>
    </visual>
    <collision>
      <origin rpy="0 0 3.1415" xyz="0.025 0.0 -0.14"/>
      <geometry>
        <mesh filename="package://amigo_description/media/meshes/logo.dae" scale="0.0016 0.0016 0.0016"/>
      </geometry>
    </collision>
  </link>
  <gazebo reference="logo">
    <material>amigo_description/logo</material>
    <turnGravityOff>false</turnGravityOff>
  </gazebo>
  <joint name="logo_joint" type="fixed">
    <parent link="base_laser"/>
    <child link="logo"/>
  </joint>
  <author>Janno Lunenburg</author>
  <license>BSD</license>
  <review notes="" status="unreviewed"/>
  <link name="torso_dummy">
    <inertial>
      <origin rpy="0 0 0" xyz="0.0 0.0 0.0"/>
      <mass value="0"/>
      <inertia ixx="0" ixy="0" ixz="0" iyy="0" iyz="0" izz="0"/>
    </inertial>
    <visual>
      <origin rpy="0 0 0" xyz="0.0 0.0 0.0"/>
      <geometry>
        <cylinder length="0.00" radius="0.0"/>
      </geometry>
      <material name="Red">
     </material>
    </visual>
    <collision>
      <origin rpy="0 0 0" xyz="0.0 0.0 0.0"/>
      <geometry>
        <cylinder length="0.00" radius="0.0"/>
      </geometry>
    </collision>
  </link>
  <gazebo reference="torso_dummy">
    <material>Gazebo/Red</material>
    <turnGravityOff>false</turnGravityOff>
  </gazebo>
  <link name="torso_laser">
    <inertial>
      <origin rpy="0 0 0" xyz="0.0 0.0 0.0"/>
      <mass value="0.5"/>
      <inertia ixx="0.0001" ixy="0" ixz="0" iyy="0.0001" iyz="0" izz="0.0001"/>
    </inertial>
    <visual>
      <origin rpy="0 0 0" xyz="-0.005 0.0 -0.065"/>
      <geometry>
        <box size="0.05 0.065 0.12"/>
      </geometry>
      <material name="Black">
     </material>
    </visual>
    <collision>
      <origin rpy="0 0 0" xyz="-0.005 0.0 -0.065"/>
      <geometry>
        <box size="0.05 0.065 0.12"/>
      </geometry>
    </collision>
  </link>
  <gazebo reference="torso_laser">
    <material>Gazebo/Black</material>
    <turnGravityOff>false</turnGravityOff>
  </gazebo>
  <joint name="torso_dummy_joint" type="fixed">
    <parent link="torso"/>
    <child link="torso_dummy"/>
    <origin rpy="0.0 -1.57 0.0" xyz="-0.0994 0.0 0.075"/>
    <axis xyz="0 1 0"/>
    <dynamics damping="0.1" friction="0"/>
    <limit effort="13.4" lower="-0.7809" upper="1.5708" velocity="1.0"/>
  </joint>
  <joint name="torso_laser_joint" type="fixed">
    <parent link="torso_dummy"/>
    <child link="torso_laser"/>
    <origin rpy="0.0 0.0 -0.05" xyz="0.0 0.0 0.0"/>
    <axis xyz="0 1 0"/>
    <dynamics damping="0.1" friction="0"/>
    <limit effort="13.4" lower="-0.7809" upper="1.5708" velocity="1.0"/>
  </joint>
  <link name="torso_lasertop">
    <inertial>
      <origin rpy="0 0 0" xyz="0.0 0.0 0.0"/>
      <mass value="0.01"/>
      <inertia ixx="0.0001" ixy="0" ixz="0" iyy="0.0001" iyz="0" izz="0.0001"/>
    </inertial>
    <visual>
      <origin rpy="0 0 0" xyz="-0.005 0.0 0.0"/>
      <geometry>
        <box size="0.05 0.065 0.01"/>
      </geometry>
      <material name="amigo_description/orange">
     </material>
    </visual>
    <collision>
      <origin rpy="0 0 0" xyz="-0.005 0.0 0.0"/>
      <geometry>
        <box size="0.05 0.065 0.01"/>
      </geometry>
    </collision>
  </link>
  <gazebo reference="torso_lasertop">
    <material>amigo_description/orange</material>
    <turnGravityOff>false</turnGravityOff>
  </gazebo>
  <joint name="torso_lasertop_joint" type="fixed">
    <parent link="torso_laser"/>
    <child link="torso_lasertop"/>
  </joint>
  <!--========BUILD HEAD======-->
  <author>Kris van Tienhoven</author>
  <license>BSD</license>
  <review notes="" status="unreviewed"/>
  <link name="head_mount">
    <inertial>
      <origin rpy="0 0 0" xyz="0.0 0.0 0.0"/>
      <mass value="0.001"/>
      <inertia ixx="0.0001" ixy="0" ixz="0" iyy="0.0001" iyz="0" izz="0.0001"/>
    </inertial>
  </link>
  <joint name="head_mount_joint" type="fixed">
    <parent link="torso"/>
    <child link="head_mount"/>
    <axis xyz="0 0 1"/>
    <origin rpy="  0.0 0.0 0.0" xyz="0.097 0.0 0.0"/>
  </joint>
  <link name="neck_pan">
    <inertial>
      <origin rpy="0 0 0" xyz="0.0 0.0 0.0335"/>
      <mass value="0.05"/>
      <inertia ixx="0.0001" ixy="0" ixz="0" iyy="0.0001" iyz="0" izz="0.0001"/>
    </inertial>
    <visual>
      <origin rpy="0 0 0" xyz="0.0 0.0 0.0335"/>
      <geometry>
        <cylinder length="0.0525" radius="0.015"/>
      </geometry>
      <material name="Black">
     </material>
    </visual>
    <collision>
      <origin rpy="0 0 0" xyz="0.0 0.0 0.0335"/>
      <geometry>
        <cylinder length="0.0525" radius="0.015"/>
      </geometry>
    </collision>
  </link>
  <gazebo reference="neck_pan">
    <material>Gazebo/Black</material>
    <turnGravityOff>false</turnGravityOff>
  </gazebo>
  <link name="neck_tilt">
    <inertial>
      <origin rpy="0 0 0" xyz="0.0 -0.0 0.0285"/>
      <mass value="0.05"/>
      <inertia ixx="0.001" ixy="0" ixz="0" iyy="0.001" iyz="0" izz="0.001"/>
    </inertial>
    <visual>
      <origin rpy="0 0 0" xyz="0.0 -0.0 0.015"/>
      <geometry>
        <mesh filename="package://amigo_description/media/meshes/necktilttextured.dae" scale="0.004 0.004 0.004"/>
      </geometry>
      <material name="amigo_description/aluminium"/>
    </visual>
    <collision>
      <origin rpy="0 0 0" xyz="0.0 -0.0 0.015"/>
      <geometry>
        <mesh filename="package://amigo_description/media/meshes/necktilttextured.dae" scale="0.004 0.004 0.004"/>
      </geometry>
    </collision>
  </link>
  <gazebo reference="neck_tilt">
    <material>amigo_description/aluminium</material>
    <turnGravityOff>false</turnGravityOff>
  </gazebo>
  <link name="head">
    <inertial>
      <origin rpy="0 0 0" xyz="0 0 0.041"/>
      <mass value="0"/>
      <inertia ixx="0" ixy="0" ixz="0" iyy="0" iyz="0" izz="0"/>
    </inertial>
    <visual>
      <origin rpy="0 0 -1.5708" xyz="0.0 0.0 0.141"/>
      <geometry>
        <mesh filename="package://amigo_description/media/meshes/headtextured.dae" scale="0.0004 0.0004 0.0004"/>
      </geometry>
      <material name="amigo_description/white"/>
    </visual>
    <collision>
      <origin rpy="0 0 -1.5708" xyz="0.0 0.0 0.141"/>
      <geometry>
        <mesh filename="package://amigo_description/media/meshes/headtextured.dae" scale="0.0004 0.0004 0.0004"/>
      </geometry>
    </collision>
  </link>
  <gazebo reference="head">
    <material>amigo_description/white</material>
    <turnGravityOff>false</turnGravityOff>
  </gazebo>
  <joint name="head_joint" type="fixed">
    <parent link="neck_tilt"/>
    <child link="head"/>
  </joint>
  <joint name="neck_pan_joint" type="revolute">
    <parent link="head_mount"/>
    <child link="neck_pan"/>
    <origin rpy="3.14 -1.5708 0.0" xyz="0.0 0.0 0.0"/>
    <axis xyz="0 0 1"/>
    <dynamics damping="0.1" friction="0"/>
    <limit effort="13.4" lower="-1.5708" upper="1.5708" velocity="1.0"/>
  </joint>
  <joint name="neck_tilt_joint" type="revolute">
    <parent link="neck_pan"/>
    <child link="neck_tilt"/>
    <origin rpy="0.0 0.0 0.0" xyz="0.0 0.0 0.0445"/>
    <axis xyz="0 1 0"/>
    <dynamics damping="0.1" friction="0.0"/>
    <limit effort="13.4" lower="-2.0" upper="2.0" velocity="1.0"/>
  </joint>
  <!--========BUILD KINECT======-->
  <joint name="top_kinect/base_kinect_joint" type="fixed">
    <origin rpy="0 0 0" xyz="0.07 0 0.07"/>
    <!-- THESE VALUES ARE ROUGH ESTIMATES!! -->
    <parent link="head"/>
    <child link="top_kinect/openni_camera"/>
  </joint>
  <link name="top_kinect/openni_camera">
    <inertial>
      <mass value="0.01"/>
      <origin xyz="0 0 0"/>
      <inertia ixx="0.001" ixy="0.0" ixz="0.0" iyy="0.001" iyz="0.0" izz="0.001"/>
    </inertial>
    <visual>
      <origin rpy="0 0 0" xyz=" 0 0 0 "/>
      <geometry>
        <box size="0 0 0"/>
        <!--mesh filename="package://amigo_description/kinect/meshes/kinect.dae" scale="0.001 0.001 0.001"/-->
        <!--<mesh filename="package://amigo_description/kinect/meshes/kinect_without_base.dae"/>-->
      </geometry>
    </visual>
    <!--<collision>
      <origin xyz="-0.0365 0.0 0.0" rpy="0 0 0" />
      <geometry>
        <box size="0.0730 .2760 0.0720"/>
      </geometry>
    </collision>-->
  </link>
  <joint name="top_kinect/kinect_depth_joint" type="fixed">
    <origin rpy="0 0 0" xyz="0 0.018 0"/>
    <parent link="top_kinect/openni_camera"/>
    <child link="top_kinect/openni_depth_frame"/>
  </joint>
  <link name="top_kinect/openni_depth_frame">
    <inertial>
      <mass value="0.01"/>
      <origin xyz="0 0 0"/>
      <inertia ixx="0.001" ixy="0.0" ixz="0.0" iyy="0.001" iyz="0.0" izz="0.001"/>
    </inertial>
  </link>
  <joint name="top_kinect/kinect_depth_optical_joint" type="fixed">
    <origin rpy="-1.570795 0 -1.570795" xyz="0 0 0"/>
    <parent link="top_kinect/openni_depth_frame"/>
    <child link="top_kinect/openni_depth_optical_frame"/>
  </joint>
  <link name="top_kinect/openni_depth_optical_frame">
    <inertial>
      <mass value="0.001"/>
      <origin xyz="0 0 0"/>
      <inertia ixx="0.0001" ixy="0.0" ixz="0.0" iyy="0.0001" iyz="0.0" izz="0.0001"/>
    </inertial>
  </link>
  <joint name="top_kinect/kinect_rgb_joint" type="fixed">
    <origin rpy="0 0 0" xyz="0 -0.005 0"/>
    <parent link="top_kinect/openni_camera"/>
    <child link="top_kinect/openni_rgb_frame"/>
  </joint>
  <link name="top_kinect/openni_rgb_frame">
    <inertial>
      <mass value="0.001"/>
      <origin xyz="0 0 0"/>
      <inertia ixx="0.0001" ixy="0.0" ixz="0.0" iyy="0.0001" iyz="0.0" izz="0.0001"/>
    </inertial>
  </link>
  <joint name="top_kinect/kinect_rgb_optical_joint" type="fixed">
    <origin rpy="-1.570795 0 -1.570795" xyz="0 0 0"/>
    <parent link="top_kinect/openni_rgb_frame"/>
    <child link="top_kinect/openni_rgb_optical_frame"/>
  </joint>
  <link name="top_kinect/openni_rgb_optical_frame">
    <inertial>
      <mass value="0.001"/>
      <origin xyz="0 0 0"/>
      <inertia ixx="0.0001" ixy="0.0" ixz="0.0" iyy="0.0001" iyz="0.0" izz="0.0001"/>
    </inertial>
  </link>
  <joint name="base_kinect/base_kinect_joint" type="fixed">
    <origin rpy="0 -0.07 0" xyz="0.3 0 0.26"/>
    <!-- THESE VALUES STILL HAVE TO BE CALIBRATED!! -->
    <parent link="base"/>
    <child link="base_kinect/openni_camera"/>
  </joint>
  <link name="base_kinect/openni_camera">
    <inertial>
      <mass value="0.01"/>
      <origin xyz="0 0 0"/>
      <inertia ixx="0.001" ixy="0.0" ixz="0.0" iyy="0.001" iyz="0.0" izz="0.001"/>
    </inertial>
    <visual>
      <origin rpy="0 0 0" xyz=" 0 0 0 "/>
      <geometry>
        <!--<box size="0 0 0"/>-->
        <!--mesh filename="package://amigo_description/description/kinect/meshes/kinect.dae" scale="0.001 0.001 0.001"/-->
        <mesh filename="package://amigo_description/media/meshes/kinect/kinect_without_base.dae"/>
      </geometry>
    </visual>
    <collision>
      <origin rpy="0 0 0" xyz=" 0 0 0 "/>
      <geometry>
        <!--<box size="0.01 0.01 0.01"/>-->
        <!--<mesh filename="package://amigo_description/description/kinect/meshes/kinect.dae" scale="0.001 0.001 0.001"/>-->
        <mesh filename="package://amigo_description/media/meshes/kinect/kinect_without_base.dae"/>
      </geometry>
    </collision>
  </link>
  <joint name="base_kinect/kinect_depth_joint" type="fixed">
    <origin rpy="0 0 0" xyz="0 0.018 0"/>
    <parent link="base_kinect/openni_camera"/>
    <child link="base_kinect/openni_depth_frame"/>
  </joint>
  <link name="base_kinect/openni_depth_frame">
    <inertial>
      <mass value="0.01"/>
      <origin xyz="0 0 0"/>
      <inertia ixx="0.001" ixy="0.0" ixz="0.0" iyy="0.001" iyz="0.0" izz="0.001"/>
    </inertial>
  </link>
  <joint name="base_kinect/kinect_depth_optical_joint" type="fixed">
    <origin rpy="-1.570795 0 -1.570795" xyz="0 0 0"/>
    <parent link="base_kinect/openni_depth_frame"/>
    <child link="base_kinect/openni_depth_optical_frame"/>
  </joint>
  <link name="base_kinect/openni_depth_optical_frame">
    <inertial>
      <mass value="0.001"/>
      <origin xyz="0 0 0"/>
      <inertia ixx="0.0001" ixy="0.0" ixz="0.0" iyy="0.0001" iyz="0.0" izz="0.0001"/>
    </inertial>
  </link>
  <joint name="base_kinect/kinect_rgb_joint" type="fixed">
    <origin rpy="0 0 0" xyz="0 -0.005 0"/>
    <parent link="base_kinect/openni_camera"/>
    <child link="base_kinect/openni_rgb_frame"/>
  </joint>
  <link name="base_kinect/openni_rgb_frame">
    <inertial>
      <mass value="0.001"/>
      <origin xyz="0 0 0"/>
      <inertia ixx="0.0001" ixy="0.0" ixz="0.0" iyy="0.0001" iyz="0.0" izz="0.0001"/>
    </inertial>
  </link>
  <joint name="base_kinect/kinect_rgb_optical_joint" type="fixed">
    <origin rpy="-1.570795 0 -1.570795" xyz="0 0 0"/>
    <parent link="base_kinect/openni_rgb_frame"/>
    <child link="base_kinect/openni_rgb_optical_frame"/>
  </joint>
  <link name="base_kinect/openni_rgb_optical_frame">
    <inertial>
      <mass value="0.001"/>
      <origin xyz="0 0 0"/>
      <inertia ixx="0.0001" ixy="0.0" ixz="0.0" iyy="0.0001" iyz="0.0" izz="0.0001"/>
    </inertial>
  </link>
  <!--========BUILD ARMS======-->
  <author>Rob Janssen, Kris van Tienhoven</author>
  <license>BSD</license>
  <review notes="" status="unreviewed"/>
  <link name="shoulder_mount_right">
    <inertial>
      <origin rpy="0 0 0" xyz="0.0 0.0 0.0"/>
      <mass value="0.15"/>
      <inertia ixx="0.01" ixy="0" ixz="0" iyy="0.01" iyz="0" izz="0.01"/>
    </inertial>
    <visual>
      <origin rpy="0 0 0 " xyz="0.0 0.0 0.0"/>
      <geometry>
        <cylinder length="0.11" radius="0.05"/>
      </geometry>
      <material name="Black">
     </material>
    </visual>
    <collision>
      <origin rpy="0 0 0 " xyz="0.0 0.0 0.0"/>
      <geometry>
        <cylinder length="0.11" radius="0.05"/>
      </geometry>
    </collision>
  </link>
  <gazebo reference="shoulder_mount_right">
    <material>Gazebo/Black</material>
    <turnGravityOff>false</turnGravityOff>
  </gazebo>
  <link name="shoulder_link1_right">
    <inertial>
      <origin rpy="0 0 0" xyz="0.0 0.0 0.0"/>
      <mass value="0.25"/>
      <inertia ixx="6.0" ixy="0" ixz="0" iyy="0.01" iyz="0" izz="0.01"/>
    </inertial>
    <visual>
      <origin rpy="0 0 0 " xyz="0.0 0.0 0.0525"/>
      <geometry>
        <cylinder length="0.015" radius="0.045"/>
      </geometry>
      <material name="Black">
     </material>
    </visual>
    <collision>
      <origin rpy="0 0 0 " xyz="0.0 0.0 0.0525"/>
      <geometry>
        <cylinder length="0.015" radius="0.045"/>
      </geometry>
    </collision>
  </link>
  <gazebo reference="shoulder_link1_right">
    <material>Gazebo/Black</material>
    <turnGravityOff>false</turnGravityOff>
  </gazebo>
  <link name="shoulder_link2_right">
    <inertial>
      <origin rpy="0 0 0" xyz="0.0 0.0 0.0"/>
      <mass value="0.15"/>
      <inertia ixx="0.01" ixy="0" ixz="0" iyy="4.04" iyz="0" izz="0.001"/>
    </inertial>
    <visual>
      <origin rpy="0 0 0" xyz="0.0 -0.06 -0.05"/>
      <geometry>
        <box size="0.035 0.01 0.1"/>
      </geometry>
      <material name="Black">
     </material>
    </visual>
    <collision>
      <origin rpy="0 0 0" xyz="0.0 -0.06 -0.05"/>
      <geometry>
        <box size="0.035 0.01 0.1"/>
      </geometry>
    </collision>
  </link>
  <gazebo reference="shoulder_link2_right">
    <material>Gazebo/Black</material>
    <turnGravityOff>false</turnGravityOff>
  </gazebo>
  <link name="upper_arm_right">
    <inertial>
      <origin rpy="0 0 0" xyz="0.0 -0.2 0.0"/>
      <mass value="2.95"/>
      <inertia ixx="0.027" ixy="0" ixz="0" iyy="0.45993" iyz="0" izz="0.004"/>
    </inertial>
    <visual>
      <origin rpy="0 0 3.1415" xyz="-0.00959 -0.19131 -0.00001"/>
      <geometry>
        <mesh filename="package://amigo_description/media/meshes/upperarmtextured.dae" scale="0.0004 0.0004 0.0004"/>
      </geometry>
      <material name="amigo_description/white"/>
    </visual>
    <collision>
      <origin rpy="0 0 3.1415" xyz="-0.00959 -0.19131 -0.00001"/>
      <geometry>
        <mesh filename="package://amigo_description/media/meshes/upperarmtextured.dae" scale="0.0004 0.0004 0.0004"/>
      </geometry>
    </collision>
  </link>
  <gazebo reference="upper_arm_right">
    <material>amigo_description/white</material>
    <turnGravityOff>false</turnGravityOff>
  </gazebo>
  <link name="elbow_link4_right">
    <inertial>
      <origin rpy="0 0 0" xyz="0.0 0.0 0.0"/>
      <mass value="0.1"/>
      <inertia ixx="0.001" ixy="0" ixz="0" iyy="0.6" iyz="0" izz="0.001"/>
    </inertial>
    <visual>
      <origin rpy="0 0 0" xyz="0.0 0.0 0.0"/>
      <geometry>
        <cylinder length="0.0" radius="0.0"/>
      </geometry>
      <material name="Grey">
     </material>
    </visual>
    <collision>
      <origin rpy="0 0 0" xyz="0.0 0.0 0.0"/>
      <geometry>
        <cylinder length="0.0" radius="0.0"/>
      </geometry>
    </collision>
  </link>
  <gazebo reference="elbow_link4_right">
    <material>Gazebo/Grey</material>
    <turnGravityOff>false</turnGravityOff>
  </gazebo>
  <link name="fore_arm_right">
    <inertial>
      <origin rpy="0.0 0 0" xyz="0.0 -0.14 0.0"/>
      <mass value="0.85"/>
      <inertia ixx="0.001" ixy="0" ixz="0" iyy="0.5" iyz="0" izz="0.001"/>
    </inertial>
    <visual>
      <origin rpy="0 -1.5708 0" xyz="0.00425 -0.14868 0.00547"/>
      <geometry>
        <mesh filename="package://amigo_description/media/meshes/forearmtextured.dae" scale="0.0004 0.0004 0.0004"/>
      </geometry>
      <material name="amigo_description/white"/>
    </visual>
    <collision>
      <origin rpy="0 -1.5708 0" xyz="0.00425 -0.14868 0.00547"/>
      <geometry>
        <mesh filename="package://amigo_description/media/meshes/forearmtextured.dae" scale="0.0004 0.0004 0.0004"/>
      </geometry>
    </collision>
  </link>
  <gazebo reference="fore_arm_right">
    <material>amigo_description/white</material>
    <turnGravityOff>false</turnGravityOff>
  </gazebo>
  <link name="wrist_link6_right">
    <inertial>
      <origin rpy="0 0 0" xyz="0.0 0.0 0.0"/>
      <mass value="0.01"/>
      <inertia ixx="0.001" ixy="0" ixz="0" iyy="0.03322" iyz="0" izz="0.001"/>
    </inertial>
    <visual>
      <origin rpy="1.5708 0 0" xyz="0.0 0.0 0.0"/>
      <geometry>
        <cylinder length="0.0" radius="0.0"/>
      </geometry>
      <material name="Black">
     </material>
    </visual>
    <collision>
      <origin rpy="1.5708 0 0" xyz="0.0 0.0 0.0"/>
      <geometry>
        <cylinder length="0.0" radius="0.0"/>
      </geometry>
    </collision>
  </link>
  <gazebo reference="wrist_link6_right">
    <material>Gazebo/Black</material>
    <turnGravityOff>false</turnGravityOff>
  </gazebo>
  <link name="hand_right">
    <inertial>
      <origin rpy="0 0 0" xyz="0.048 0.0 0.0"/>
      <mass value="0.2"/>
      <inertia ixx="0.01" ixy="0" ixz="0" iyy="0.01" iyz="0" izz="0.0622"/>
    </inertial>
    <visual>
      <origin rpy="0 0 0" xyz="0.048 0.0 0.0"/>
      <geometry>
        <box size="0.080 0.085 0.038"/>
      </geometry>
      <material name="Grey">
     </material>
    </visual>
    <collision>
      <origin rpy="0 0 0" xyz="0.048 0.0 0.0"/>
      <geometry>
        <box size="0.080 0.085 0.038"/>
      </geometry>
    </collision>
  </link>
  <gazebo reference="hand_right">
    <material>Gazebo/Grey</material>
    <turnGravityOff>false</turnGravityOff>
  </gazebo>
  <link name="finger1_right">
    <inertial>
      <origin rpy="0 0 0" xyz="0.0 0.0 -0.03"/>
      <mass value="0.01"/>
      <inertia ixx="0.01" ixy="0" ixz="0" iyy="0.01" iyz="0" izz="0.01"/>
    </inertial>
    <visual>
      <origin rpy="0 0 0" xyz="0.0 0.0 -0.03"/>
      <geometry>
        <box size="0.018 0.018 0.06"/>
      </geometry>
      <material name="Black">
     </material>
    </visual>
    <collision>
      <origin rpy="0 0 0" xyz="0.0 0.0 -0.03"/>
      <geometry>
        <box size="0.018 0.018 0.06"/>
      </geometry>
    </collision>
  </link>
  <gazebo reference="finger1_right">
    <material>Gazebo/Black</material>
    <turnGravityOff>false</turnGravityOff>
  </gazebo>
  <gazebo reference="finger1_right">
    <mu1 value="100.0"/>
    <mu2 value="100.0"/>
  </gazebo>
  <link name="finger1_phalanx_right">
    <inertial>
      <origin rpy="0 0 0" xyz="0.0 0.0 0"/>
      <mass value="0.01"/>
      <inertia ixx="0.001" ixy="0" ixz="0" iyy="0.001" iyz="0" izz="0.001"/>
    </inertial>
    <visual>
      <origin rpy="0 0 0" xyz="0.0 0.0 0"/>
      <geometry>
        <cylinder length="0.019" radius="0.009"/>
      </geometry>
      <material name="White">
     </material>
    </visual>
    <collision>
      <origin rpy="0 0 0" xyz="0.0 0.0 0"/>
      <geometry>
        <cylinder length="0.019" radius="0.009"/>
      </geometry>
    </collision>
  </link>
  <gazebo reference="finger1_phalanx_right">
    <material>Gazebo/White</material>
    <turnGravityOff>false</turnGravityOff>
  </gazebo>
  <link name="finger1_tip_right">
    <inertial>
      <origin rpy="0 0 0" xyz="0.0 0.0 -0.03"/>
      <mass value="0.01"/>
      <inertia ixx="0.00037" ixy="0" ixz="0" iyy="0.00052" iyz="0" izz="0.00052"/>
    </inertial>
    <visual>
      <origin rpy="0 0 0" xyz="0.0 0.0 -0.03"/>
      <geometry>
        <box size="0.018 0.018 0.06"/>
      </geometry>
      <material name="Black">
     </material>
    </visual>
    <collision>
      <origin rpy="0 0 0" xyz="0.0 0.0 -0.03"/>
      <geometry>
        <box size="0.018 0.018 0.06"/>
      </geometry>
    </collision>
  </link>
  <gazebo reference="finger1_tip_right">
    <material>Gazebo/Black</material>
    <turnGravityOff>false</turnGravityOff>
  </gazebo>
  <gazebo reference="finger1_tip_right">
    <mu1 value="100.0"/>
    <mu2 value="100.0"/>
  </gazebo>
  <link name="finger1_tip_phalanx_right">
    <inertial>
      <origin rpy="0 0 0" xyz="0.0 0.0 0"/>
      <mass value="0.01"/>
      <inertia ixx="0.001" ixy="0" ixz="0" iyy="0.001" iyz="0" izz="0.001"/>
    </inertial>
    <visual>
      <origin rpy="0 0 0" xyz="0.0 0.0 0"/>
      <geometry>
        <cylinder length="0.017" radius="0.009"/>
      </geometry>
      <material name="White">
     </material>
    </visual>
    <collision>
      <origin rpy="0 0 0" xyz="0.0 0.0 0"/>
      <geometry>
        <cylinder length="0.017" radius="0.009"/>
      </geometry>
    </collision>
  </link>
  <gazebo reference="finger1_tip_phalanx_right">
    <material>Gazebo/White</material>
    <turnGravityOff>false</turnGravityOff>
  </gazebo>
  <link name="finger2_right">
    <inertial>
      <origin rpy="0 0 0" xyz="0.0 0.0 -0.03"/>
      <mass value="0.01"/>
      <inertia ixx="0.01" ixy="0" ixz="0" iyy="0.01" iyz="0" izz="0.01"/>
    </inertial>
    <visual>
      <origin rpy="0 0 0" xyz="0.0 0.0 -0.03"/>
      <geometry>
        <box size="0.018 0.018 0.06"/>
      </geometry>
      <material name="Black">
     </material>
    </visual>
    <collision>
      <origin rpy="0 0 0" xyz="0.0 0.0 -0.03"/>
      <geometry>
        <box size="0.018 0.018 0.06"/>
      </geometry>
    </collision>
  </link>
  <gazebo reference="finger2_right">
    <material>Gazebo/Black</material>
    <turnGravityOff>false</turnGravityOff>
  </gazebo>
  <gazebo reference="finger2_right">
    <mu1 value="100.0"/>
    <mu2 value="100.0"/>
  </gazebo>
  <link name="finger2_phalanx_right">
    <inertial>
      <origin rpy="0 0 0" xyz="0.0 0.0 0"/>
      <mass value="0.01"/>
      <inertia ixx="0.001" ixy="0" ixz="0" iyy="0.001" iyz="0" izz="0.001"/>
    </inertial>
    <visual>
      <origin rpy="0 0 0" xyz="0.0 0.0 0"/>
      <geometry>
        <cylinder length="0.019" radius="0.009"/>
      </geometry>
      <material name="White">
     </material>
    </visual>
    <collision>
      <origin rpy="0 0 0" xyz="0.0 0.0 0"/>
      <geometry>
        <cylinder length="0.019" radius="0.009"/>
      </geometry>
    </collision>
  </link>
  <gazebo reference="finger2_phalanx_right">
    <material>Gazebo/White</material>
    <turnGravityOff>false</turnGravityOff>
  </gazebo>
  <link name="finger2_tip_right">
    <inertial>
      <origin rpy="0 0 0" xyz="0.0 0.0 -0.03"/>
      <mass value="0.01"/>
      <inertia ixx="0.00037" ixy="0" ixz="0" iyy="0.00052" iyz="0" izz="0.00052"/>
    </inertial>
    <visual>
      <origin rpy="0 0 0" xyz="0.0 0.0 -0.03"/>
      <geometry>
        <box size="0.018 0.018 0.06"/>
      </geometry>
      <material name="Black">
     </material>
    </visual>
    <collision>
      <origin rpy="0 0 0" xyz="0.0 0.0 -0.03"/>
      <geometry>
        <box size="0.018 0.018 0.06"/>
      </geometry>
    </collision>
  </link>
  <gazebo reference="finger2_tip_right">
    <material>Gazebo/Black</material>
    <turnGravityOff>false</turnGravityOff>
  </gazebo>
  <gazebo reference="finger2_tip_right">
    <mu1 value="100.0"/>
    <mu2 value="100.0"/>
  </gazebo>
  <link name="finger2_tip_phalanx_right">
    <inertial>
      <origin rpy="0 0 0" xyz="0.0 0.0 0"/>
      <mass value="0.01"/>
      <inertia ixx="0.001" ixy="0" ixz="0" iyy="0.001" iyz="0" izz="0.001"/>
    </inertial>
    <visual>
      <origin rpy="0 0 0" xyz="0.0 0.0 0"/>
      <geometry>
        <cylinder length="0.017" radius="0.009"/>
      </geometry>
      <material name="White">
     </material>
    </visual>
    <collision>
      <origin rpy="0 0 0" xyz="0.0 0.0 0"/>
      <geometry>
        <cylinder length="0.017" radius="0.009"/>
      </geometry>
    </collision>
  </link>
  <gazebo reference="finger2_tip_phalanx_right">
    <material>Gazebo/White</material>
    <turnGravityOff>false</turnGravityOff>
  </gazebo>
  <link name="grippoint_right">
    <inertial>
      <origin rpy="0 0 0" xyz="-0.1 0.0 0.0"/>
      <mass value="0.01"/>
      <inertia ixx="0.0001" ixy="0" ixz="0" iyy="0.0001" iyz="0" izz="0.0001"/>
    </inertial>
    <visual>
      <origin rpy="0 0 0 " xyz="-0.1 0.0 0.0"/>
      <geometry>
        <box size="0.0 0.0 0.0"/>
      </geometry>
      <material name="Blue">
     </material>
    </visual>
    <collision>
      <origin rpy="0 0 0 " xyz="-0.1 0.0 0.0"/>
      <geometry>
        <box size="0.0 0.0 0.0"/>
      </geometry>
    </collision>
  </link>
  <gazebo reference="grippoint_right">
    <material>Gazebo/Blue</material>
    <turnGravityOff>false</turnGravityOff>
  </gazebo>
  <joint name="shoulder_mount_joint_right" type="fixed">
    <parent link="torso"/>
    <child link="shoulder_mount_right"/>
    <origin rpy="0 0 0.0" xyz="0.05 0.22 0.0"/>
  </joint>
  <joint name="shoulder_yaw_joint_right" type="revolute">
    <parent link="shoulder_mount_right"/>
    <child link="shoulder_link1_right"/>
    <origin rpy="-1.5708 -1.5708 0" xyz="0 0 0"/>
    <axis xyz="+1 0 0"/>
    <dynamics damping="4.0" friction="4.87"/>
    <limit effort="13.4" lower="-1.57" upper="0.0" velocity="1.0"/>
  </joint>
  <joint name="shoulder_pitch_joint_right" type="revolute">
    <parent link="shoulder_link1_right"/>
    <child link="shoulder_link2_right"/>
    <origin rpy="-1.5708  0 0" xyz="0.0 0.0 0.0"/>
    <axis xyz="0 -1 0"/>
    <dynamics damping="4.0" friction="6.06"/>
    <limit effort="13.4" lower="-1.57" upper="1.57" velocity="1.0"/>
  </joint>
  <joint name="shoulder_roll_joint_right" type="revolute">
    <parent link="shoulder_link2_right"/>
    <child link="upper_arm_right"/>
    <origin rpy="1.5708 0 0.0" xyz="0.0 0.0 0.0"/>
    <axis xyz="0 1.0 0"/>
    <dynamics damping="3.8" friction="2.216"/>
    <limit effort="9.8" lower="-1.57" upper="1.57" velocity="1.0"/>
  </joint>
  <joint name="elbow_pitch_joint_right" type="revolute">
    <parent link="upper_arm_right"/>
    <child link="elbow_link4_right"/>
    <origin rpy="-1.5708 0 0" xyz="0.01 -0.32 0.0"/>
    <axis xyz="0 -1 0"/>
    <dynamics damping="3" friction="1.18"/>
    <limit effort="4.5" lower="0.0" upper="2.23" velocity="1.0"/>
  </joint>
  <joint name="elbow_roll_joint_right" type="revolute">
    <parent link="elbow_link4_right"/>
    <child link="fore_arm_right"/>
    <origin rpy="1.5708 0 0" xyz="0.0 0.0 0.0"/>
    <axis xyz="0 1.0 0"/>
    <dynamics damping="3.5" friction="1.35"/>
    <limit effort="4.5" lower="-1.83" upper="1.83" velocity="1.0"/>
  </joint>
  <joint name="wrist_pitch_joint_right" type="revolute">
    <parent link="fore_arm_right"/>
    <child link="wrist_link6_right"/>
    <origin rpy="-1.5708 0 -1.5708" xyz="0.01 -0.28 0.0"/>
    <axis xyz="0 -1 0"/>
    <dynamics damping="0.35" friction="0.63"/>
    <limit effort="1" lower="-0.95" upper="0.95" velocity="1.0"/>
  </joint>
  <joint name="wrist_yaw_joint_right" type="revolute">
    <parent link="wrist_link6_right"/>
    <child link="hand_right"/>
    <origin rpy="0 0 0" xyz="0.0 0.0 0.0"/>
    <axis xyz="0 0 1.01"/>
    <dynamics damping="0.3" friction="0.68"/>
    <limit effort="1" lower="-0.61" upper="0.61" velocity="1.0"/>
  </joint>
  <joint name="finger1_joint_right" type="revolute">
    <parent link="hand_right"/>
    <child link="finger1_right"/>
    <origin rpy="0 -1.57 0" xyz=" 0.075 0.02 0"/>
    <axis xyz="1 0 0"/>
    <dynamics damping="0.5" friction="1.0"/>
    <limit effort="3" lower="0.2" upper="1" velocity="1.0"/>
  </joint>
  <joint name="finger1_phalanx_joint_right" type="fixed">
    <parent link="finger1_right"/>
    <child link="finger1_phalanx_right"/>
    <origin rpy="0 1.57 0" xyz="0 0 -0.06"/>
  </joint>
  <joint name="finger1_tip_joint_right" type="revolute">
    <parent link="finger1_right"/>
    <child link="finger1_tip_right"/>
    <origin rpy="0 0 0" xyz=" 0 0.0 -0.06"/>
    <axis xyz="1 0 0"/>
    <dynamics damping="0.5" friction="1.0"/>
    <limit effort="3" lower="-0.6" upper="-0.2" velocity="1.0"/>
  </joint>
  <joint name="finger1_tip_phalanx_joint_right" type="fixed">
    <parent link="finger1_tip_right"/>
    <child link="finger1_tip_phalanx_right"/>
    <origin rpy="0 1.57 0" xyz="0 0 -0.06"/>
  </joint>
  <joint name="finger2_joint_right" type="revolute">
    <parent link="hand_right"/>
    <child link="finger2_right"/>
    <origin rpy="0 -1.57 0" xyz="0.075 -0.02 0"/>
    <axis xyz="-1 0 0"/>
    <dynamics damping="0.5" friction="1.0"/>
    <limit effort="3" lower="0.2" upper="1" velocity="1.0"/>
  </joint>
  <joint name="finger2_phalanx_joint_right" type="fixed">
    <parent link="finger2_right"/>
    <child link="finger2_phalanx_right"/>
    <origin rpy="0 1.57 0" xyz="0 0 -0.06"/>
  </joint>
  <joint name="finger2_tip_joint_right" type="revolute">
    <parent link="finger2_right"/>
    <child link="finger2_tip_right"/>
    <origin rpy="0 0 0" xyz="0 0 -0.06"/>
    <axis xyz="-1 0 0"/>
    <dynamics damping="0.5" friction="1.0"/>
    <limit effort="3" lower="-0.6" upper="-0.2" velocity="1.0"/>
  </joint>
  <joint name="finger2_tip_phalanx_joint_right" type="fixed">
    <parent link="finger2_tip_right"/>
    <child link="finger2_tip_phalanx_right"/>
    <origin rpy="0 1.57 0" xyz="0 0 -0.06"/>
  </joint>
  <joint name="grippoint_joint_right" type="fixed">
    <parent link="hand_right"/>
    <child link="grippoint_right"/>
    <origin rpy="0 0 0" xyz="0.14 0.0 0.0"/>
  </joint>
  <link name="shoulder_mount_left">
    <inertial>
      <origin rpy="0 0 0" xyz="0.0 0.0 0.0"/>
      <mass value="0.15"/>
      <inertia ixx="0.01" ixy="0" ixz="0" iyy="0.01" iyz="0" izz="0.01"/>
    </inertial>
    <visual>
      <origin rpy="0 0 0 " xyz="0.0 0.0 0.0"/>
      <geometry>
        <cylinder length="0.11" radius="0.05"/>
      </geometry>
      <material name="Black">
     </material>
    </visual>
    <collision>
      <origin rpy="0 0 0 " xyz="0.0 0.0 0.0"/>
      <geometry>
        <cylinder length="0.11" radius="0.05"/>
      </geometry>
    </collision>
  </link>
  <gazebo reference="shoulder_mount_left">
    <material>Gazebo/Black</material>
    <turnGravityOff>false</turnGravityOff>
  </gazebo>
  <link name="shoulder_link1_left">
    <inertial>
      <origin rpy="0 0 0" xyz="0.0 0.0 0.0"/>
      <mass value="0.25"/>
      <inertia ixx="6.0" ixy="0" ixz="0" iyy="0.01" iyz="0" izz="0.01"/>
    </inertial>
    <visual>
      <origin rpy="0 0 0 " xyz="0.0 0.0 -0.0525"/>
      <geometry>
        <cylinder length="0.015" radius="0.045"/>
      </geometry>
      <material name="Black">
     </material>
    </visual>
    <collision>
      <origin rpy="0 0 0 " xyz="0.0 0.0 -0.0525"/>
      <geometry>
        <cylinder length="0.015" radius="0.045"/>
      </geometry>
    </collision>
  </link>
  <gazebo reference="shoulder_link1_left">
    <material>Gazebo/Black</material>
    <turnGravityOff>false</turnGravityOff>
  </gazebo>
  <link name="shoulder_link2_left">
    <inertial>
      <origin rpy="0 0 0" xyz="0.0 0.0 0.0"/>
      <mass value="0.15"/>
      <inertia ixx="0.01" ixy="0" ixz="0" iyy="4.04" iyz="0" izz="0.001"/>
    </inertial>
    <visual>
      <origin rpy="0 0 0" xyz="0.0 0.06 -0.05"/>
      <geometry>
        <box size="0.035 0.01 0.1"/>
      </geometry>
      <material name="Black">
     </material>
    </visual>
    <collision>
      <origin rpy="0 0 0" xyz="0.0 0.06 -0.05"/>
      <geometry>
        <box size="0.035 0.01 0.1"/>
      </geometry>
    </collision>
  </link>
  <gazebo reference="shoulder_link2_left">
    <material>Gazebo/Black</material>
    <turnGravityOff>false</turnGravityOff>
  </gazebo>
  <link name="upper_arm_left">
    <inertial>
      <origin rpy="0 0 0" xyz="0.0 -0.2 0.0"/>
      <mass value="2.95"/>
      <inertia ixx="0.027" ixy="0" ixz="0" iyy="0.45993" iyz="0" izz="0.004"/>
    </inertial>
    <visual>
      <origin rpy="0 0 3.1415" xyz="-0.00959 -0.19131 -0.00001"/>
      <geometry>
        <mesh filename="package://amigo_description/media/meshes/upperarmtextured.dae" scale="0.0004 0.0004 0.0004"/>
      </geometry>
      <material name="amigo_description/white"/>
    </visual>
    <collision>
      <origin rpy="0 0 3.1415" xyz="-0.00959 -0.19131 -0.00001"/>
      <geometry>
        <mesh filename="package://amigo_description/media/meshes/upperarmtextured.dae" scale="0.0004 0.0004 0.0004"/>
      </geometry>
    </collision>
  </link>
  <gazebo reference="upper_arm_left">
    <material>amigo_description/white</material>
    <turnGravityOff>false</turnGravityOff>
  </gazebo>
  <link name="elbow_link4_left">
    <inertial>
      <origin rpy="0 0 0" xyz="0.0 0.0 0.0"/>
      <mass value="0.1"/>
      <inertia ixx="0.001" ixy="0" ixz="0" iyy="0.6" iyz="0" izz="0.001"/>
    </inertial>
    <visual>
      <origin rpy="0 0 0" xyz="0.0 0.0 0.0"/>
      <geometry>
        <cylinder length="0.0" radius="0.0"/>
      </geometry>
      <material name="Grey">
     </material>
    </visual>
    <collision>
      <origin rpy="0 0 0" xyz="0.0 0.0 0.0"/>
      <geometry>
        <cylinder length="0.0" radius="0.0"/>
      </geometry>
    </collision>
  </link>
  <gazebo reference="elbow_link4_left">
    <material>Gazebo/Grey</material>
    <turnGravityOff>false</turnGravityOff>
  </gazebo>
  <link name="fore_arm_left">
    <inertial>
      <origin rpy="0.0 0 0" xyz="0.0 -0.14 0.0"/>
      <mass value="0.85"/>
      <inertia ixx="0.001" ixy="0" ixz="0" iyy="0.5" iyz="0" izz="0.001"/>
    </inertial>
    <visual>
      <origin rpy="0 -1.5708 0" xyz="0.00425 -0.14868 0.00547"/>
      <geometry>
        <mesh filename="package://amigo_description/media/meshes/forearmtextured.dae" scale="0.0004 0.0004 0.0004"/>
      </geometry>
      <material name="amigo_description/white"/>
    </visual>
    <collision>
      <origin rpy="0 -1.5708 0" xyz="0.00425 -0.14868 0.00547"/>
      <geometry>
        <mesh filename="package://amigo_description/media/meshes/forearmtextured.dae" scale="0.0004 0.0004 0.0004"/>
      </geometry>
    </collision>
  </link>
  <gazebo reference="fore_arm_left">
    <material>amigo_description/white</material>
    <turnGravityOff>false</turnGravityOff>
  </gazebo>
  <link name="wrist_link6_left">
    <inertial>
      <origin rpy="0 0 0" xyz="0.0 0.0 0.0"/>
      <mass value="0.01"/>
      <inertia ixx="0.001" ixy="0" ixz="0" iyy="0.03322" iyz="0" izz="0.001"/>
    </inertial>
    <visual>
      <origin rpy="1.5708 0 0" xyz="0.0 0.0 0.0"/>
      <geometry>
        <cylinder length="0.0" radius="0.0"/>
      </geometry>
      <material name="Black">
     </material>
    </visual>
    <collision>
      <origin rpy="1.5708 0 0" xyz="0.0 0.0 0.0"/>
      <geometry>
        <cylinder length="0.0" radius="0.0"/>
      </geometry>
    </collision>
  </link>
  <gazebo reference="wrist_link6_left">
    <material>Gazebo/Black</material>
    <turnGravityOff>false</turnGravityOff>
  </gazebo>
  <link name="hand_left">
    <inertial>
      <origin rpy="0 0 0" xyz="0.048 0.0 0.0"/>
      <mass value="0.2"/>
      <inertia ixx="0.01" ixy="0" ixz="0" iyy="0.01" iyz="0" izz="0.0622"/>
    </inertial>
    <visual>
      <origin rpy="0 0 0" xyz="0.048 0.0 0.0"/>
      <geometry>
        <box size="0.080 0.085 0.038"/>
      </geometry>
      <material name="Grey">
     </material>
    </visual>
    <collision>
      <origin rpy="0 0 0" xyz="0.048 0.0 0.0"/>
      <geometry>
        <box size="0.080 0.085 0.038"/>
      </geometry>
    </collision>
  </link>
  <gazebo reference="hand_left">
    <material>Gazebo/Grey</material>
    <turnGravityOff>false</turnGravityOff>
  </gazebo>
  <link name="finger1_left">
    <inertial>
      <origin rpy="0 0 0" xyz="0.0 0.0 -0.03"/>
      <mass value="0.01"/>
      <inertia ixx="0.01" ixy="0" ixz="0" iyy="0.01" iyz="0" izz="0.01"/>
    </inertial>
    <visual>
      <origin rpy="0 0 0" xyz="0.0 0.0 -0.03"/>
      <geometry>
        <box size="0.018 0.018 0.06"/>
      </geometry>
      <material name="Black">
     </material>
    </visual>
    <collision>
      <origin rpy="0 0 0" xyz="0.0 0.0 -0.03"/>
      <geometry>
        <box size="0.018 0.018 0.06"/>
      </geometry>
    </collision>
  </link>
  <gazebo reference="finger1_left">
    <material>Gazebo/Black</material>
    <turnGravityOff>false</turnGravityOff>
  </gazebo>
  <gazebo reference="finger1_left">
    <mu1 value="100.0"/>
    <mu2 value="100.0"/>
  </gazebo>
  <link name="finger1_phalanx_left">
    <inertial>
      <origin rpy="0 0 0" xyz="0.0 0.0 0"/>
      <mass value="0.01"/>
      <inertia ixx="0.001" ixy="0" ixz="0" iyy="0.001" iyz="0" izz="0.001"/>
    </inertial>
    <visual>
      <origin rpy="0 0 0" xyz="0.0 0.0 0"/>
      <geometry>
        <cylinder length="0.019" radius="0.009"/>
      </geometry>
      <material name="White">
     </material>
    </visual>
    <collision>
      <origin rpy="0 0 0" xyz="0.0 0.0 0"/>
      <geometry>
        <cylinder length="0.019" radius="0.009"/>
      </geometry>
    </collision>
  </link>
  <gazebo reference="finger1_phalanx_left">
    <material>Gazebo/White</material>
    <turnGravityOff>false</turnGravityOff>
  </gazebo>
  <link name="finger1_tip_left">
    <inertial>
      <origin rpy="0 0 0" xyz="0.0 0.0 -0.03"/>
      <mass value="0.01"/>
      <inertia ixx="0.00037" ixy="0" ixz="0" iyy="0.00052" iyz="0" izz="0.00052"/>
    </inertial>
    <visual>
      <origin rpy="0 0 0" xyz="0.0 0.0 -0.03"/>
      <geometry>
        <box size="0.018 0.018 0.06"/>
      </geometry>
      <material name="Black">
     </material>
    </visual>
    <collision>
      <origin rpy="0 0 0" xyz="0.0 0.0 -0.03"/>
      <geometry>
        <box size="0.018 0.018 0.06"/>
      </geometry>
    </collision>
  </link>
  <gazebo reference="finger1_tip_left">
    <material>Gazebo/Black</material>
    <turnGravityOff>false</turnGravityOff>
  </gazebo>
  <gazebo reference="finger1_tip_left">
    <mu1 value="100.0"/>
    <mu2 value="100.0"/>
  </gazebo>
  <link name="finger1_tip_phalanx_left">
    <inertial>
      <origin rpy="0 0 0" xyz="0.0 0.0 0"/>
      <mass value="0.01"/>
      <inertia ixx="0.001" ixy="0" ixz="0" iyy="0.001" iyz="0" izz="0.001"/>
    </inertial>
    <visual>
      <origin rpy="0 0 0" xyz="0.0 0.0 0"/>
      <geometry>
        <cylinder length="0.017" radius="0.009"/>
      </geometry>
      <material name="White">
     </material>
    </visual>
    <collision>
      <origin rpy="0 0 0" xyz="0.0 0.0 0"/>
      <geometry>
        <cylinder length="0.017" radius="0.009"/>
      </geometry>
    </collision>
  </link>
  <gazebo reference="finger1_tip_phalanx_left">
    <material>Gazebo/White</material>
    <turnGravityOff>false</turnGravityOff>
  </gazebo>
  <link name="finger2_left">
    <inertial>
      <origin rpy="0 0 0" xyz="0.0 0.0 -0.03"/>
      <mass value="0.01"/>
      <inertia ixx="0.01" ixy="0" ixz="0" iyy="0.01" iyz="0" izz="0.01"/>
    </inertial>
    <visual>
      <origin rpy="0 0 0" xyz="0.0 0.0 -0.03"/>
      <geometry>
        <box size="0.018 0.018 0.06"/>
      </geometry>
      <material name="Black">
     </material>
    </visual>
    <collision>
      <origin rpy="0 0 0" xyz="0.0 0.0 -0.03"/>
      <geometry>
        <box size="0.018 0.018 0.06"/>
      </geometry>
    </collision>
  </link>
  <gazebo reference="finger2_left">
    <material>Gazebo/Black</material>
    <turnGravityOff>false</turnGravityOff>
  </gazebo>
  <gazebo reference="finger2_left">
    <mu1 value="100.0"/>
    <mu2 value="100.0"/>
  </gazebo>
  <link name="finger2_phalanx_left">
    <inertial>
      <origin rpy="0 0 0" xyz="0.0 0.0 0"/>
      <mass value="0.01"/>
      <inertia ixx="0.001" ixy="0" ixz="0" iyy="0.001" iyz="0" izz="0.001"/>
    </inertial>
    <visual>
      <origin rpy="0 0 0" xyz="0.0 0.0 0"/>
      <geometry>
        <cylinder length="0.019" radius="0.009"/>
      </geometry>
      <material name="White">
     </material>
    </visual>
    <collision>
      <origin rpy="0 0 0" xyz="0.0 0.0 0"/>
      <geometry>
        <cylinder length="0.019" radius="0.009"/>
      </geometry>
    </collision>
  </link>
  <gazebo reference="finger2_phalanx_left">
    <material>Gazebo/White</material>
    <turnGravityOff>false</turnGravityOff>
  </gazebo>
  <link name="finger2_tip_left">
    <inertial>
      <origin rpy="0 0 0" xyz="0.0 0.0 -0.03"/>
      <mass value="0.01"/>
      <inertia ixx="0.00037" ixy="0" ixz="0" iyy="0.00052" iyz="0" izz="0.00052"/>
    </inertial>
    <visual>
      <origin rpy="0 0 0" xyz="0.0 0.0 -0.03"/>
      <geometry>
        <box size="0.018 0.018 0.06"/>
      </geometry>
      <material name="Black">
     </material>
    </visual>
    <collision>
      <origin rpy="0 0 0" xyz="0.0 0.0 -0.03"/>
      <geometry>
        <box size="0.018 0.018 0.06"/>
      </geometry>
    </collision>
  </link>
  <gazebo reference="finger2_tip_left">
    <material>Gazebo/Black</material>
    <turnGravityOff>false</turnGravityOff>
  </gazebo>
  <gazebo reference="finger2_tip_left">
    <mu1 value="100.0"/>
    <mu2 value="100.0"/>
  </gazebo>
  <link name="finger2_tip_phalanx_left">
    <inertial>
      <origin rpy="0 0 0" xyz="0.0 0.0 0"/>
      <mass value="0.01"/>
      <inertia ixx="0.001" ixy="0" ixz="0" iyy="0.001" iyz="0" izz="0.001"/>
    </inertial>
    <visual>
      <origin rpy="0 0 0" xyz="0.0 0.0 0"/>
      <geometry>
        <cylinder length="0.017" radius="0.009"/>
      </geometry>
      <material name="White">
     </material>
    </visual>
    <collision>
      <origin rpy="0 0 0" xyz="0.0 0.0 0"/>
      <geometry>
        <cylinder length="0.017" radius="0.009"/>
      </geometry>
    </collision>
  </link>
  <gazebo reference="finger2_tip_phalanx_left">
    <material>Gazebo/White</material>
    <turnGravityOff>false</turnGravityOff>
  </gazebo>
  <link name="grippoint_left">
    <inertial>
      <origin rpy="0 0 0" xyz="-0.1 0.0 0.0"/>
      <mass value="0.01"/>
      <inertia ixx="0.0001" ixy="0" ixz="0" iyy="0.0001" iyz="0" izz="0.0001"/>
    </inertial>
    <visual>
      <origin rpy="0 0 0 " xyz="-0.1 0.0 0.0"/>
      <geometry>
        <box size="0.0 0.0 0.0"/>
      </geometry>
      <material name="Blue">
     </material>
    </visual>
    <collision>
      <origin rpy="0 0 0 " xyz="-0.1 0.0 0.0"/>
      <geometry>
        <box size="0.0 0.0 0.0"/>
      </geometry>
    </collision>
  </link>
  <gazebo reference="grippoint_left">
    <material>Gazebo/Blue</material>
    <turnGravityOff>false</turnGravityOff>
  </gazebo>
  <joint name="shoulder_mount_joint_left" type="fixed">
    <parent link="torso"/>
    <child link="shoulder_mount_left"/>
    <origin rpy="0 0 0.0" xyz="0.05 -0.22 0.0"/>
  </joint>
  <joint name="shoulder_yaw_joint_left" type="revolute">
    <parent link="shoulder_mount_left"/>
    <child link="shoulder_link1_left"/>
    <origin rpy="-1.5708 -1.5708 0" xyz="0 0 0"/>
    <axis xyz="-1 0 0"/>
    <dynamics damping="4.0" friction="4.87"/>
    <limit effort="13.4" lower="-1.57" upper="0.0" velocity="1.0"/>
  </joint>
  <joint name="shoulder_pitch_joint_left" type="revolute">
    <parent link="shoulder_link1_left"/>
    <child link="shoulder_link2_left"/>
    <origin rpy="-1.5708  0 0" xyz="0.0 0.0 0.0"/>
    <axis xyz="0 -1 0"/>
    <dynamics damping="4.0" friction="6.06"/>
    <limit effort="13.4" lower="-1.57" upper="1.57" velocity="1.0"/>
  </joint>
  <joint name="shoulder_roll_joint_left" type="revolute">
    <parent link="shoulder_link2_left"/>
    <child link="upper_arm_left"/>
    <origin rpy="1.5708 0 0.0" xyz="0.0 0.0 0.0"/>
    <axis xyz="0 -1.0 0"/>
    <dynamics damping="3.8" friction="2.216"/>
    <limit effort="9.8" lower="-1.57" upper="1.57" velocity="1.0"/>
  </joint>
  <joint name="elbow_pitch_joint_left" type="revolute">
    <parent link="upper_arm_left"/>
    <child link="elbow_link4_left"/>
    <origin rpy="-1.5708 0 0" xyz="0.01 -0.32 0.0"/>
    <axis xyz="0 -1 0"/>
    <dynamics damping="3" friction="1.18"/>
    <limit effort="4.5" lower="0.0" upper="2.23" velocity="1.0"/>
  </joint>
  <joint name="elbow_roll_joint_left" type="revolute">
    <parent link="elbow_link4_left"/>
    <child link="fore_arm_left"/>
    <origin rpy="1.5708 0 0" xyz="0.0 0.0 0.0"/>
    <axis xyz="0 -1.0 0"/>
    <dynamics damping="3.5" friction="1.35"/>
    <limit effort="4.5" lower="-1.83" upper="1.83" velocity="1.0"/>
  </joint>
  <joint name="wrist_pitch_joint_left" type="revolute">
    <parent link="fore_arm_left"/>
    <child link="wrist_link6_left"/>
    <origin rpy="-1.5708 0 -1.5708" xyz="0.01 -0.28 0.0"/>
    <axis xyz="0 -1 0"/>
    <dynamics damping="0.35" friction="0.63"/>
    <limit effort="1" lower="-0.95" upper="0.95" velocity="1.0"/>
  </joint>
  <joint name="wrist_yaw_joint_left" type="revolute">
    <parent link="wrist_link6_left"/>
    <child link="hand_left"/>
    <origin rpy="0 0 0" xyz="0.0 0.0 0.0"/>
    <axis xyz="0 0 -1.01"/>
    <dynamics damping="0.3" friction="0.68"/>
    <limit effort="1" lower="-0.61" upper="0.61" velocity="1.0"/>
  </joint>
  <joint name="finger1_joint_left" type="revolute">
    <parent link="hand_left"/>
    <child link="finger1_left"/>
    <origin rpy="0 -1.57 0" xyz=" 0.075 0.02 0"/>
    <axis xyz="1 0 0"/>
    <dynamics damping="0.5" friction="1.0"/>
    <limit effort="3" lower="0.2" upper="1" velocity="1.0"/>
  </joint>
  <joint name="finger1_phalanx_joint_left" type="fixed">
    <parent link="finger1_left"/>
    <child link="finger1_phalanx_left"/>
    <origin rpy="0 1.57 0" xyz="0 0 -0.06"/>
  </joint>
  <joint name="finger1_tip_joint_left" type="revolute">
    <parent link="finger1_left"/>
    <child link="finger1_tip_left"/>
    <origin rpy="0 0 0" xyz=" 0 0.0 -0.06"/>
    <axis xyz="1 0 0"/>
    <dynamics damping="0.5" friction="1.0"/>
    <limit effort="3" lower="-0.6" upper="-0.2" velocity="1.0"/>
  </joint>
  <joint name="finger1_tip_phalanx_joint_left" type="fixed">
    <parent link="finger1_tip_left"/>
    <child link="finger1_tip_phalanx_left"/>
    <origin rpy="0 1.57 0" xyz="0 0 -0.06"/>
  </joint>
  <joint name="finger2_joint_left" type="revolute">
    <parent link="hand_left"/>
    <child link="finger2_left"/>
    <origin rpy="0 -1.57 0" xyz="0.075 -0.02 0"/>
    <axis xyz="-1 0 0"/>
    <dynamics damping="0.5" friction="1.0"/>
    <limit effort="3" lower="0.2" upper="1" velocity="1.0"/>
  </joint>
  <joint name="finger2_phalanx_joint_left" type="fixed">
    <parent link="finger2_left"/>
    <child link="finger2_phalanx_left"/>
    <origin rpy="0 1.57 0" xyz="0 0 -0.06"/>
  </joint>
  <joint name="finger2_tip_joint_left" type="revolute">
    <parent link="finger2_left"/>
    <child link="finger2_tip_left"/>
    <origin rpy="0 0 0" xyz="0 0 -0.06"/>
    <axis xyz="-1 0 0"/>
    <dynamics damping="0.5" friction="1.0"/>
    <limit effort="3" lower="-0.6" upper="-0.2" velocity="1.0"/>
  </joint>
  <joint name="finger2_tip_phalanx_joint_left" type="fixed">
    <parent link="finger2_tip_left"/>
    <child link="finger2_tip_phalanx_left"/>
    <origin rpy="0 1.57 0" xyz="0 0 -0.06"/>
  </joint>
  <joint name="grippoint_joint_left" type="fixed">
    <parent link="hand_left"/>
    <child link="grippoint_left"/>
    <origin rpy="0 0 0" xyz="0.14 0.0 0.0"/>
  </joint>
  <!--extra arm visuals-->
  <author>Kris van Tienhoven</author>
  <license>BSD</license>
  <review notes="" status="unreviewed"/>
  <link name="upper_arm_top_right">
    <inertial>
      <origin rpy="0 0 0" xyz="0.0 0.0 0.0"/>
      <mass value="0.01"/>
      <inertia ixx="0.027" ixy="0" ixz="0" iyy="0.027" iyz="0" izz="0.004"/>
    </inertial>
    <visual>
      <origin rpy="0 0 0" xyz="0.0 0.0 0.0"/>
      <geometry>
        <cylinder length="0.02" radius="0.0561"/>
      </geometry>
      <material name="Black">
     </material>
    </visual>
    <collision>
      <origin rpy="0 0 0" xyz="0.0 0.0 0.0"/>
      <geometry>
        <cylinder length="0.02" radius="0.0561"/>
      </geometry>
    </collision>
  </link>
  <gazebo reference="upper_arm_top_right">
    <material>Gazebo/Black</material>
    <turnGravityOff>false</turnGravityOff>
  </gazebo>
  <link name="elbow_extra_block_right">
    <inertial>
      <origin rpy="0 0 0" xyz="0.0 0.0 0.0"/>
      <mass value="0.01"/>
      <inertia ixx="0.001" ixy="0" ixz="0" iyy="0.001" iyz="0" izz="0.001"/>
    </inertial>
    <visual>
      <origin rpy="0 0 0" xyz="-0.036 0.0 0.02"/>
      <geometry>
        <box size="0.015 0.08 0.06"/>
      </geometry>
      <material name="Black">
     </material>
    </visual>
    <collision>
      <origin rpy="0 0 0" xyz="-0.036 0.0 0.02"/>
      <geometry>
        <box size="0.015 0.08 0.06"/>
      </geometry>
    </collision>
  </link>
  <gazebo reference="elbow_extra_block_right">
    <material>Gazebo/Black</material>
    <turnGravityOff>false</turnGravityOff>
  </gazebo>
  <link name="elbow_extra_block2_right">
    <inertial>
      <origin rpy="0 0 0" xyz="0.0 0.0 0.0"/>
      <mass value="0.01"/>
      <inertia ixx="0.001" ixy="0" ixz="0" iyy="0.001" iyz="0" izz="0.001"/>
    </inertial>
    <visual>
      <origin rpy="1.5708 0 0" xyz="0.0 0.0 0.0"/>
      <geometry>
        <cylinder length="0.08" radius="0.03"/>
      </geometry>
      <material name="Grey">
     </material>
    </visual>
    <collision>
      <origin rpy="1.5708 0 0" xyz="0.0 0.0 0.0"/>
      <geometry>
        <cylinder length="0.08" radius="0.03"/>
      </geometry>
    </collision>
  </link>
  <gazebo reference="elbow_extra_block2_right">
    <material>Gazebo/Grey</material>
    <turnGravityOff>false</turnGravityOff>
  </gazebo>
  <link name="fore_arm_top_right">
    <inertial>
      <origin rpy="0 0 0" xyz="0.0 0.0 0.0"/>
      <mass value="0.01"/>
      <inertia ixx="0.0054" ixy="0" ixz="0" iyy="0.0054" iyz="0" izz="0.0004"/>
    </inertial>
    <visual>
      <origin rpy="0 0 0" xyz="0.0 0.0 0.01"/>
      <geometry>
        <cylinder length="0.01" radius="0.037"/>
      </geometry>
      <material name="Black">
     </material>
    </visual>
    <collision>
      <origin rpy="0 0 0" xyz="0.0 0.0 0.01"/>
      <geometry>
        <cylinder length="0.01" radius="0.037"/>
      </geometry>
    </collision>
  </link>
  <gazebo reference="fore_arm_top_right">
    <material>Gazebo/Black</material>
    <turnGravityOff>false</turnGravityOff>
  </gazebo>
  <link name="wrist_visual_right">
    <inertial>
      <origin rpy="0 0 0" xyz="0.0 0.0 0.0"/>
      <mass value="0.01"/>
      <inertia ixx="0.001" ixy="0" ixz="0" iyy="0.001" iyz="0" izz="0.001"/>
    </inertial>
    <visual>
      <origin rpy="0 0 0" xyz="0.0 0.0 0.0"/>
      <geometry>
        <cylinder length="0.06" radius="0.018"/>
      </geometry>
      <material name="Grey">
     </material>
    </visual>
    <collision>
      <origin rpy="0 0 0" xyz="0.0 0.0 0.0"/>
      <geometry>
        <cylinder length="0.06" radius="0.018"/>
      </geometry>
    </collision>
  </link>
  <gazebo reference="wrist_visual_right">
    <material>Gazebo/Grey</material>
    <turnGravityOff>false</turnGravityOff>
  </gazebo>
  <link name="wrist_to_hand_block_right">
    <inertial>
      <origin rpy="0 0 0" xyz="0.0 0.0 0.0"/>
      <mass value="0.01"/>
      <inertia ixx="0.001" ixy="0" ixz="0" iyy="0.001" iyz="0" izz="0.001"/>
    </inertial>
    <visual>
      <origin rpy="0 0 0" xyz="0.0 0.0 0.0"/>
      <geometry>
        <box size="0.03 0.02 0.038"/>
      </geometry>
      <material name="Grey">
     </material>
    </visual>
    <collision>
      <origin rpy="0 0 0" xyz="0.0 0.0 0.0"/>
      <geometry>
        <box size="0.03 0.02 0.038"/>
      </geometry>
    </collision>
  </link>
  <gazebo reference="wrist_to_hand_block_right">
    <material>Gazebo/Grey</material>
    <turnGravityOff>false</turnGravityOff>
  </gazebo>
  <joint name="upper_arm_top_joint_right" type="fixed">
    <parent link="upper_arm_right"/>
    <child link="upper_arm_top_right"/>
    <origin rpy="1.5708 0 0.0" xyz="-0.01 -0.1 0.0"/>
  </joint>
  <joint name="elbow_extra_block_joint_right" type="fixed">
    <parent link="upper_arm_right"/>
    <child link="elbow_extra_block_right"/>
    <origin rpy="-1.5708 0 0" xyz="0.0 -0.31 0.0"/>
  </joint>
  <joint name="elbow_extra_block2_joint_right" type="fixed">
    <parent link="upper_arm_right"/>
    <child link="elbow_extra_block2_right"/>
    <origin rpy="-1.5708 0 0" xyz="0.0 -0.31 0.0"/>
  </joint>
  <joint name="fore_arm_top_joint_right" type="fixed">
    <parent link="fore_arm_right"/>
    <child link="fore_arm_top_right"/>
    <origin rpy="1.5708 0 0" xyz="0.002 -0.011 0.0"/>
  </joint>
  <joint name="wrist_visual_joint_right" type="fixed">
    <parent link="wrist_link6_right"/>
    <child link="wrist_visual_right"/>
    <origin rpy="1.5708 0 0" xyz="-0.02 0.0 0.0"/>
  </joint>
  <joint name="wrist_to_hand_block_joint_right" type="fixed">
    <parent link="wrist_link6_right"/>
    <child link="wrist_to_hand_block_right"/>
    <origin rpy="0 0 0" xyz="0.0 0.0 0.0"/>
  </joint>
  <link name="upper_arm_top_left">
    <inertial>
      <origin rpy="0 0 0" xyz="0.0 0.0 0.0"/>
      <mass value="0.01"/>
      <inertia ixx="0.027" ixy="0" ixz="0" iyy="0.027" iyz="0" izz="0.004"/>
    </inertial>
    <visual>
      <origin rpy="0 0 0" xyz="0.0 0.0 0.0"/>
      <geometry>
        <cylinder length="0.02" radius="0.0561"/>
      </geometry>
      <material name="Black">
     </material>
    </visual>
    <collision>
      <origin rpy="0 0 0" xyz="0.0 0.0 0.0"/>
      <geometry>
        <cylinder length="0.02" radius="0.0561"/>
      </geometry>
    </collision>
  </link>
  <gazebo reference="upper_arm_top_left">
    <material>Gazebo/Black</material>
    <turnGravityOff>false</turnGravityOff>
  </gazebo>
  <link name="elbow_extra_block_left">
    <inertial>
      <origin rpy="0 0 0" xyz="0.0 0.0 0.0"/>
      <mass value="0.01"/>
      <inertia ixx="0.001" ixy="0" ixz="0" iyy="0.001" iyz="0" izz="0.001"/>
    </inertial>
    <visual>
      <origin rpy="0 0 0" xyz="-0.036 0.0 0.02"/>
      <geometry>
        <box size="0.015 0.08 0.06"/>
      </geometry>
      <material name="Black">
     </material>
    </visual>
    <collision>
      <origin rpy="0 0 0" xyz="-0.036 0.0 0.02"/>
      <geometry>
        <box size="0.015 0.08 0.06"/>
      </geometry>
    </collision>
  </link>
  <gazebo reference="elbow_extra_block_left">
    <material>Gazebo/Black</material>
    <turnGravityOff>false</turnGravityOff>
  </gazebo>
  <link name="elbow_extra_block2_left">
    <inertial>
      <origin rpy="0 0 0" xyz="0.0 0.0 0.0"/>
      <mass value="0.01"/>
      <inertia ixx="0.001" ixy="0" ixz="0" iyy="0.001" iyz="0" izz="0.001"/>
    </inertial>
    <visual>
      <origin rpy="1.5708 0 0" xyz="0.0 0.0 0.0"/>
      <geometry>
        <cylinder length="0.08" radius="0.03"/>
      </geometry>
      <material name="Grey">
     </material>
    </visual>
    <collision>
      <origin rpy="1.5708 0 0" xyz="0.0 0.0 0.0"/>
      <geometry>
        <cylinder length="0.08" radius="0.03"/>
      </geometry>
    </collision>
  </link>
  <gazebo reference="elbow_extra_block2_left">
    <material>Gazebo/Grey</material>
    <turnGravityOff>false</turnGravityOff>
  </gazebo>
  <link name="fore_arm_top_left">
    <inertial>
      <origin rpy="0 0 0" xyz="0.0 0.0 0.0"/>
      <mass value="0.01"/>
      <inertia ixx="0.0054" ixy="0" ixz="0" iyy="0.0054" iyz="0" izz="0.0004"/>
    </inertial>
    <visual>
      <origin rpy="0 0 0" xyz="0.0 0.0 0.01"/>
      <geometry>
        <cylinder length="0.01" radius="0.037"/>
      </geometry>
      <material name="Black">
     </material>
    </visual>
    <collision>
      <origin rpy="0 0 0" xyz="0.0 0.0 0.01"/>
      <geometry>
        <cylinder length="0.01" radius="0.037"/>
      </geometry>
    </collision>
  </link>
  <gazebo reference="fore_arm_top_left">
    <material>Gazebo/Black</material>
    <turnGravityOff>false</turnGravityOff>
  </gazebo>
  <link name="wrist_visual_left">
    <inertial>
      <origin rpy="0 0 0" xyz="0.0 0.0 0.0"/>
      <mass value="0.01"/>
      <inertia ixx="0.001" ixy="0" ixz="0" iyy="0.001" iyz="0" izz="0.001"/>
    </inertial>
    <visual>
      <origin rpy="0 0 0" xyz="0.0 0.0 0.0"/>
      <geometry>
        <cylinder length="0.06" radius="0.018"/>
      </geometry>
      <material name="Grey">
     </material>
    </visual>
    <collision>
      <origin rpy="0 0 0" xyz="0.0 0.0 0.0"/>
      <geometry>
        <cylinder length="0.06" radius="0.018"/>
      </geometry>
    </collision>
  </link>
  <gazebo reference="wrist_visual_left">
    <material>Gazebo/Grey</material>
    <turnGravityOff>false</turnGravityOff>
  </gazebo>
  <link name="wrist_to_hand_block_left">
    <inertial>
      <origin rpy="0 0 0" xyz="0.0 0.0 0.0"/>
      <mass value="0.01"/>
      <inertia ixx="0.001" ixy="0" ixz="0" iyy="0.001" iyz="0" izz="0.001"/>
    </inertial>
    <visual>
      <origin rpy="0 0 0" xyz="0.0 0.0 0.0"/>
      <geometry>
        <box size="0.03 0.02 0.038"/>
      </geometry>
      <material name="Grey">
     </material>
    </visual>
    <collision>
      <origin rpy="0 0 0" xyz="0.0 0.0 0.0"/>
      <geometry>
        <box size="0.03 0.02 0.038"/>
      </geometry>
    </collision>
  </link>
  <gazebo reference="wrist_to_hand_block_left">
    <material>Gazebo/Grey</material>
    <turnGravityOff>false</turnGravityOff>
  </gazebo>
  <joint name="upper_arm_top_joint_left" type="fixed">
    <parent link="upper_arm_left"/>
    <child link="upper_arm_top_left"/>
    <origin rpy="1.5708 0 0.0" xyz="-0.01 -0.1 0.0"/>
  </joint>
  <joint name="elbow_extra_block_joint_left" type="fixed">
    <parent link="upper_arm_left"/>
    <child link="elbow_extra_block_left"/>
    <origin rpy="-1.5708 0 0" xyz="0.0 -0.31 0.0"/>
  </joint>
  <joint name="elbow_extra_block2_joint_left" type="fixed">
    <parent link="upper_arm_left"/>
    <child link="elbow_extra_block2_left"/>
    <origin rpy="-1.5708 0 0" xyz="0.0 -0.31 0.0"/>
  </joint>
  <joint name="fore_arm_top_joint_left" type="fixed">
    <parent link="fore_arm_left"/>
    <child link="fore_arm_top_left"/>
    <origin rpy="1.5708 0 0" xyz="0.002 -0.011 0.0"/>
  </joint>
  <joint name="wrist_visual_joint_left" type="fixed">
    <parent link="wrist_link6_left"/>
    <child link="wrist_visual_left"/>
    <origin rpy="1.5708 0 0" xyz="-0.02 0.0 0.0"/>
  </joint>
  <joint name="wrist_to_hand_block_joint_left" type="fixed">
    <parent link="wrist_link6_left"/>
    <child link="wrist_to_hand_block_left"/>
    <origin rpy="0 0 0" xyz="0.0 0.0 0.0"/>
  </joint>
  <!-- GAZEBO -->
  <gazebo>
    <controller:gazebo_ros_controller_manager name="gazebo_ros_controller_manager" plugin="libgazebo_ros_controller_manager.so">
      <alwaysOn>true</alwaysOn>
      <updateRate>1000.0</updateRate>
      <interface:audio name="gazebo_ros_controller_manager_dummy_iface"/>
    </controller:gazebo_ros_controller_manager>
    <controller:gazebo_ros_imu name="imu_controller" plugin="libgazebo_ros_imu.so">
      <alwaysOn>true</alwaysOn>
      <updateRate>1000.0</updateRate>
      <bodyName>base_link</bodyName>
      <topicName>/imu/data</topicName>
      <serviceName>imu_service</serviceName>
      <gaussianNoise>2.89e-08</gaussianNoise>
      <xyzOffset>0 0 0</xyzOffset>
      <rpyOffset>0 0 0</rpyOffset>
      <interface:position name="imu_position_iface"/>
    </controller:gazebo_ros_imu>
  </gazebo>
  <gazebo reference="front_laser">
    <sensor:ray name="front_laser_sensor">
      <origin>0.0 0.0 0.0</origin>
      <rayCount>683</rayCount>
      <rangeCount>683</rangeCount>
      <laserCount>1</laserCount>
      <displayRays>false</displayRays>
      <minAngle>-120</minAngle>
      <maxAngle> 120</maxAngle>
      <minRange>0.05</minRange>
      <maxRange>10.0</maxRange>
      <resRange>0.01</resRange>
      <updateRate>100.0</updateRate>
      <controller:gazebo_ros_laser name="front_laser_sensor_controller" plugin="libgazebo_ros_laser.so">
        <gaussianNoise>0.005</gaussianNoise>
        <alwaysOn>true</alwaysOn>
        <updateRate>15.0</updateRate>
        <topicName>base_scan</topicName>
        <frameName>/front_laser</frameName>
        <hokuyoMinIntensity>101</hokuyoMinIntensity>
        <interface:laser name="front_laser_sensor_iface"/>
      </controller:gazebo_ros_laser>
    </sensor:ray>
  </gazebo>
  <gazebo reference="torso_laser">
    <sensor:ray name="torso_laser_sensor">
      <origin>0.0 0.0 0.0</origin>
      <rayCount>683</rayCount>
      <rangeCount>683</rangeCount>
      <laserCount>1</laserCount>
      <displayRays>false</displayRays>
      <minAngle>-120</minAngle>
      <maxAngle> 120</maxAngle>
      <minRange>0.05</minRange>
      <maxRange>10.0</maxRange>
      <resRange>0.01</resRange>
      <updateRate>100.0</updateRate>
      <controller:gazebo_ros_laser name="torso_laser_sensor_controller" plugin="libgazebo_ros_laser.so">
        <gaussianNoise>0.005</gaussianNoise>
        <alwaysOn>true</alwaysOn>
        <updateRate>15.0</updateRate>
        <topicName>top_scan</topicName>
        <frameName>/torso_laser</frameName>
        <hokuyoMinIntensity>101</hokuyoMinIntensity>
        <interface:laser name="torso_laser_sensor_iface"/>
      </controller:gazebo_ros_laser>
    </sensor:ray>
  </gazebo>
  <gazebo reference="openni_camera">
    <sensor:camera name="openni_camera">
      <imageFormat>R8G8B8</imageFormat>
      <imageSize>640 480</imageSize>
      <hfov>60</hfov>
      <nearClip>0.05</nearClip>
      <farClip>3</farClip>
      <updateRate>20</updateRate>
      <baseline>0.1</baseline>
      <controller:gazebo_ros_openni_kinect name="kinect_camera_controller" plugin="libkinect_controller.so">
        <!-- THIS IS THE FORKED VERSION UNTIL NOW (OCT16 2012) THE VERSION IN GAZEBO_PLUGINS WAS NOT SHOWING DEPTH IMAGE PROPERLY!! -->
        <alwaysOn>true</alwaysOn>
        <updateRate>20</updateRate>
        <cameraName>camera</cameraName>
        <imageTopicName>/camera/rgb/image_rect_color</imageTopicName>
        <cameraInfoTopicName>/camera/rgb/camera_info</cameraInfoTopicName>
        <depthImageTopicName>/camera/depth_registered/image</depthImageTopicName>
        <depthImageCameraInfoTopicName>/camera/depth/camera_info</depthImageCameraInfoTopicName>
        <pointCloudTopicName>/camera/rgb/points</pointCloudTopicName>
        <frameName>/openni_depth_optical_frame</frameName>
        <distortionK1>0.0</distortionK1>
        <distortionK2>0.0</distortionK2>
        <distortionK3>0.0</distortionK3>
        <distortionT1>0.0</distortionT1>
        <distortionT2>0.0</distortionT2>
        <CxPrime>0.0</CxPrime>
        <Cx>0.0</Cx>
        <Cy>0.0</Cy>
        <focalLength>0.0</focalLength>
        <hackBaseline>0.0</hackBaseline>
      </controller:gazebo_ros_openni_kinect>
    </sensor:camera>
  </gazebo>
  <gazebo reference="base_kinect_openni_camera">
    <sensor:camera name="base_kinect_openni_camera">
      <imageFormat>R8G8B8</imageFormat>
      <imageSize>640 480</imageSize>
      <hfov>60</hfov>
      <nearClip>0.05</nearClip>
      <farClip>3</farClip>
      <updateRate>20</updateRate>
      <baseline>0.1</baseline>
      <controller:gazebo_ros_openni_kinect name="base_kinect_camera_controller" plugin="libkinect_controller.so">
        <!-- THIS IS THE FORKED VERSION UNTIL NOW (OCT16 2012) THE VERSION IN GAZEBO_PLUGINS WAS NOT SHOWING DEPTH IMAGE PROPERLY!! -->
        <alwaysOn>true</alwaysOn>
        <updateRate>20</updateRate>
        <cameraName>base_camera</cameraName>
        <imageTopicName>/base_camera/rgb/image_color</imageTopicName>
        <cameraInfoTopicName>/base_camera/rgb/camera_info</cameraInfoTopicName>
        <depthImageTopicName>/base_camera/depth/image</depthImageTopicName>
        <depthImageCameraInfoTopicName>/base_camera/depth/camera_info</depthImageCameraInfoTopicName>
        <pointCloudTopicName>/base_camera/rgb/points</pointCloudTopicName>
        <frameName>/base_kinect_openni_depth_optical_frame</frameName>
        <distortionK1>0.0</distortionK1>
        <distortionK2>0.0</distortionK2>
        <distortionK3>0.0</distortionK3>
        <distortionT1>0.0</distortionT1>
        <distortionT2>0.0</distortionT2>
        <CxPrime>0.0</CxPrime>
        <Cx>0.0</Cx>
        <Cy>0.0</Cy>
        <focalLength>0.0</focalLength>
        <hackBaseline>0.0</hackBaseline>
      </controller:gazebo_ros_openni_kinect>
    </sensor:camera>
  </gazebo>
  <transmission name="spindle_trans" type="pr2_mechanism_model/SimpleTransmission">
    <actuator name="spindle_motor"/>
    <joint name="torso_joint"/>
    <mechanicalReduction>1</mechanicalReduction>
    <motorTorqueConstant>1</motorTorqueConstant>
  </transmission>
  <transmission name="shoulder_yaw_trans_left" type="pr2_mechanism_model/SimpleTransmission">
    <actuator name="shoulder_yaw_motor_left"/>
    <joint name="shoulder_yaw_joint_left"/>
    <mechanicalReduction>1</mechanicalReduction>
    <motorTorqueConstant>1</motorTorqueConstant>
  </transmission>
  <transmission name="shoulder_pitch_trans_left" type="pr2_mechanism_model/SimpleTransmission">
    <actuator name="shoulder_pitch_motor_left"/>
    <joint name="shoulder_pitch_joint_left"/>
    <mechanicalReduction>1</mechanicalReduction>
    <motorTorqueConstant>1</motorTorqueConstant>
  </transmission>
  <transmission name="shoulder_roll_trans_left" type="pr2_mechanism_model/SimpleTransmission">
    <actuator name="shoulder_roll_motor_left"/>
    <joint name="shoulder_roll_joint_left"/>
    <mechanicalReduction>1</mechanicalReduction>
    <motorTorqueConstant>1</motorTorqueConstant>
  </transmission>
  <transmission name="elbow_pitch_trans_left" type="pr2_mechanism_model/SimpleTransmission">
    <actuator name="elbow_pitch_motor_left"/>
    <joint name="elbow_pitch_joint_left"/>
    <mechanicalReduction>1</mechanicalReduction>
    <motorTorqueConstant>1</motorTorqueConstant>
  </transmission>
  <transmission name="elbow_roll_trans_left" type="pr2_mechanism_model/SimpleTransmission">
    <actuator name="elbow_roll_motor_left"/>
    <joint name="elbow_roll_joint_left"/>
    <mechanicalReduction>1</mechanicalReduction>
    <motorTorqueConstant>1</motorTorqueConstant>
  </transmission>
  <transmission name="wrist_yaw_trans_left" type="pr2_mechanism_model/SimpleTransmission">
    <actuator name="wrist_yaw_motor_left"/>
    <joint name="wrist_yaw_joint_left"/>
    <mechanicalReduction>1</mechanicalReduction>
    <motorTorqueConstant>1</motorTorqueConstant>
  </transmission>
  <transmission name="wrist_pitch_trans_left" type="pr2_mechanism_model/SimpleTransmission">
    <actuator name="wrist_pitch_motor_left"/>
    <joint name="wrist_pitch_joint_left"/>
    <mechanicalReduction>1</mechanicalReduction>
    <motorTorqueConstant>1</motorTorqueConstant>
  </transmission>
  <transmission name="finger1_trans_left" type="pr2_mechanism_model/SimpleTransmission">
    <actuator name="finger1_motor_left"/>
    <joint name="finger1_joint_left"/>
    <mechanicalReduction>1</mechanicalReduction>
    <motorTorqueConstant>1</motorTorqueConstant>
  </transmission>
  <transmission name="finger2_trans_left" type="pr2_mechanism_model/SimpleTransmission">
    <actuator name="finger2_motor_left"/>
    <joint name="finger2_joint_left"/>
    <mechanicalReduction>1</mechanicalReduction>
    <motorTorqueConstant>1</motorTorqueConstant>
  </transmission>
  <transmission name="finger1_tip_trans_left" type="pr2_mechanism_model/SimpleTransmission">
    <actuator name="finger1_tip_motor_left"/>
    <joint name="finger1_tip_joint_left"/>
    <mechanicalReduction>1</mechanicalReduction>
    <motorTorqueConstant>1</motorTorqueConstant>
  </transmission>
  <transmission name="finger2_tip_trans_left" type="pr2_mechanism_model/SimpleTransmission">
    <actuator name="finger2_tip_motor_left"/>
    <joint name="finger2_tip_joint_left"/>
    <mechanicalReduction>1</mechanicalReduction>
    <motorTorqueConstant>1</motorTorqueConstant>
  </transmission>
  <transmission name="shoulder_yaw_trans_right" type="pr2_mechanism_model/SimpleTransmission">
    <actuator name="shoulder_yaw_motor_right"/>
    <joint name="shoulder_yaw_joint_right"/>
    <mechanicalReduction>1</mechanicalReduction>
    <motorTorqueConstant>1</motorTorqueConstant>
  </transmission>
  <transmission name="shoulder_pitch_trans_right" type="pr2_mechanism_model/SimpleTransmission">
    <actuator name="shoulder_pitch_motor_right"/>
    <joint name="shoulder_pitch_joint_right"/>
    <mechanicalReduction>1</mechanicalReduction>
    <motorTorqueConstant>1</motorTorqueConstant>
  </transmission>
  <transmission name="shoulder_roll_trans_right" type="pr2_mechanism_model/SimpleTransmission">
    <actuator name="shoulder_roll_motor_right"/>
    <joint name="shoulder_roll_joint_right"/>
    <mechanicalReduction>1</mechanicalReduction>
    <motorTorqueConstant>1</motorTorqueConstant>
  </transmission>
  <transmission name="elbow_pitch_trans_right" type="pr2_mechanism_model/SimpleTransmission">
    <actuator name="elbow_pitch_motor_right"/>
    <joint name="elbow_pitch_joint_right"/>
    <mechanicalReduction>1</mechanicalReduction>
    <motorTorqueConstant>1</motorTorqueConstant>
  </transmission>
  <transmission name="elbow_roll_trans_right" type="pr2_mechanism_model/SimpleTransmission">
    <actuator name="elbow_roll_motor_right"/>
    <joint name="elbow_roll_joint_right"/>
    <mechanicalReduction>1</mechanicalReduction>
    <motorTorqueConstant>1</motorTorqueConstant>
  </transmission>
  <transmission name="wrist_yaw_trans_right" type="pr2_mechanism_model/SimpleTransmission">
    <actuator name="wrist_yaw_motor_right"/>
    <joint name="wrist_yaw_joint_right"/>
    <mechanicalReduction>1</mechanicalReduction>
    <motorTorqueConstant>1</motorTorqueConstant>
  </transmission>
  <transmission name="wrist_pitch_trans_right" type="pr2_mechanism_model/SimpleTransmission">
    <actuator name="wrist_pitch_motor_right"/>
    <joint name="wrist_pitch_joint_right"/>
    <mechanicalReduction>1</mechanicalReduction>
    <motorTorqueConstant>1</motorTorqueConstant>
  </transmission>
  <transmission name="finger1_trans_right" type="pr2_mechanism_model/SimpleTransmission">
    <actuator name="finger1_motor_right"/>
    <joint name="finger1_joint_right"/>
    <mechanicalReduction>1</mechanicalReduction>
    <motorTorqueConstant>1</motorTorqueConstant>
  </transmission>
  <transmission name="finger2_trans_right" type="pr2_mechanism_model/SimpleTransmission">
    <actuator name="finger2_motor_right"/>
    <joint name="finger2_joint_right"/>
    <mechanicalReduction>1</mechanicalReduction>
    <motorTorqueConstant>1</motorTorqueConstant>
  </transmission>
  <transmission name="finger1_tip_trans_right" type="pr2_mechanism_model/SimpleTransmission">
    <actuator name="finger1_tip_motor_right"/>
    <joint name="finger1_tip_joint_right"/>
    <mechanicalReduction>1</mechanicalReduction>
    <motorTorqueConstant>1</motorTorqueConstant>
  </transmission>
  <transmission name="finger2_tip_trans_right" type="pr2_mechanism_model/SimpleTransmission">
    <actuator name="finger2_tip_motor_right"/>
    <joint name="finger2_tip_joint_right"/>
    <mechanicalReduction>1</mechanicalReduction>
    <motorTorqueConstant>1</motorTorqueConstant>
  </transmission>
  <transmission name="wheel_inner_trans_left_front" type="pr2_mechanism_model/SimpleTransmission">
    <actuator name="wheel_inner_motor_left_front"/>
    <joint name="wheel_inner_joint_left_front"/>
    <mechanicalReduction>1</mechanicalReduction>
    <motorTorqueConstant>1</motorTorqueConstant>
  </transmission>
  <transmission name="wheel_inner_trans_right_front" type="pr2_mechanism_model/SimpleTransmission">
    <actuator name="wheel_inner_motor_right_front"/>
    <joint name="wheel_inner_joint_right_front"/>
    <mechanicalReduction>1</mechanicalReduction>
    <motorTorqueConstant>1</motorTorqueConstant>
  </transmission>
  <transmission name="wheel_inner_trans_left_rear" type="pr2_mechanism_model/SimpleTransmission">
    <actuator name="wheel_inner_motor_left_rear"/>
    <joint name="wheel_inner_joint_left_rear"/>
    <mechanicalReduction>1</mechanicalReduction>
    <motorTorqueConstant>1</motorTorqueConstant>
  </transmission>
  <transmission name="wheel_inner_trans_right_rear" type="pr2_mechanism_model/SimpleTransmission">
    <actuator name="wheel_inner_motor_right_rear"/>
    <joint name="wheel_inner_joint_right_rear"/>
    <mechanicalReduction>1</mechanicalReduction>
    <motorTorqueConstant>1</motorTorqueConstant>
  </transmission>
  <transmission name="omniwheel_trans_left_front" type="pr2_mechanism_model/SimpleTransmission">
    <actuator name="omniwheel_motor_left_front"/>
    <joint name="omni_sphere1_joint_left_front"/>
    <mechanicalReduction>1</mechanicalReduction>
    <motorTorqueConstant>1</motorTorqueConstant>
  </transmission>
  <transmission name="omniwheel_trans_right_front" type="pr2_mechanism_model/SimpleTransmission">
    <actuator name="omniwheel_motor_right_front"/>
    <joint name="omni_sphere1_joint_right_front"/>
    <mechanicalReduction>1</mechanicalReduction>
    <motorTorqueConstant>1</motorTorqueConstant>
  </transmission>
  <transmission name="omniwheel_trans_left_rear" type="pr2_mechanism_model/SimpleTransmission">
    <actuator name="omniwheel_motor_left_rear"/>
    <joint name="omni_sphere1_joint_left_rear"/>
    <mechanicalReduction>1</mechanicalReduction>
    <motorTorqueConstant>1</motorTorqueConstant>
  </transmission>
  <transmission name="omniwheel_trans_right_rear" type="pr2_mechanism_model/SimpleTransmission">
    <actuator name="omniwheel_motor_right_rear"/>
    <joint name="omni_sphere1_joint_right_rear"/>
    <mechanicalReduction>1</mechanicalReduction>
    <motorTorqueConstant>1</motorTorqueConstant>
  </transmission>
  <transmission name="omniwheel_trans_left_front" type="pr2_mechanism_model/SimpleTransmission">
    <actuator name="omniwheel_motor_left_front"/>
    <joint name="omni_sphere2_joint_left_front"/>
    <mechanicalReduction>1</mechanicalReduction>
    <motorTorqueConstant>1</motorTorqueConstant>
  </transmission>
  <transmission name="omniwheel_trans_right_front" type="pr2_mechanism_model/SimpleTransmission">
    <actuator name="omniwheel_motor_right_front"/>
    <joint name="omni_sphere2_joint_right_front"/>
    <mechanicalReduction>1</mechanicalReduction>
    <motorTorqueConstant>1</motorTorqueConstant>
  </transmission>
  <transmission name="omniwheel_trans_left_rear" type="pr2_mechanism_model/SimpleTransmission">
    <actuator name="omniwheel_motor_left_rear"/>
    <joint name="omni_sphere2_joint_left_rear"/>
    <mechanicalReduction>1</mechanicalReduction>
    <motorTorqueConstant>1</motorTorqueConstant>
  </transmission>
  <transmission name="omniwheel_trans_right_rear" type="pr2_mechanism_model/SimpleTransmission">
    <actuator name="omniwheel_motor_right_rear"/>
    <joint name="omni_sphere2_joint_right_rear"/>
    <mechanicalReduction>1</mechanicalReduction>
    <motorTorqueConstant>1</motorTorqueConstant>
  </transmission>
  <transmission name="omniwheel_trans_left_front" type="pr2_mechanism_model/SimpleTransmission">
    <actuator name="omniwheel_motor_left_front"/>
    <joint name="omni_sphere3_joint_left_front"/>
    <mechanicalReduction>1</mechanicalReduction>
    <motorTorqueConstant>1</motorTorqueConstant>
  </transmission>
  <transmission name="omniwheel_trans_right_front" type="pr2_mechanism_model/SimpleTransmission">
    <actuator name="omniwheel_motor_right_front"/>
    <joint name="omni_sphere3_joint_right_front"/>
    <mechanicalReduction>1</mechanicalReduction>
    <motorTorqueConstant>1</motorTorqueConstant>
  </transmission>
  <transmission name="omniwheel_trans_left_rear" type="pr2_mechanism_model/SimpleTransmission">
    <actuator name="omniwheel_motor_left_rear"/>
    <joint name="omni_sphere3_joint_left_rear"/>
    <mechanicalReduction>1</mechanicalReduction>
    <motorTorqueConstant>1</motorTorqueConstant>
  </transmission>
  <transmission name="omniwheel_trans_right_rear" type="pr2_mechanism_model/SimpleTransmission">
    <actuator name="omniwheel_motor_right_rear"/>
    <joint name="omni_sphere3_joint_right_rear"/>
    <mechanicalReduction>1</mechanicalReduction>
    <motorTorqueConstant>1</motorTorqueConstant>
  </transmission>
  <transmission name="omniwheel_trans_left_front" type="pr2_mechanism_model/SimpleTransmission">
    <actuator name="omniwheel_motor_left_front"/>
    <joint name="omni_sphere4_joint_left_front"/>
    <mechanicalReduction>1</mechanicalReduction>
    <motorTorqueConstant>1</motorTorqueConstant>
  </transmission>
  <transmission name="omniwheel_trans_right_front" type="pr2_mechanism_model/SimpleTransmission">
    <actuator name="omniwheel_motor_right_front"/>
    <joint name="omni_sphere4_joint_right_front"/>
    <mechanicalReduction>1</mechanicalReduction>
    <motorTorqueConstant>1</motorTorqueConstant>
  </transmission>
  <transmission name="omniwheel_trans_left_rear" type="pr2_mechanism_model/SimpleTransmission">
    <actuator name="omniwheel_motor_left_rear"/>
    <joint name="omni_sphere4_joint_left_rear"/>
    <mechanicalReduction>1</mechanicalReduction>
    <motorTorqueConstant>1</motorTorqueConstant>
  </transmission>
  <transmission name="omniwheel_trans_right_rear" type="pr2_mechanism_model/SimpleTransmission">
    <actuator name="omniwheel_motor_right_rear"/>
    <joint name="omni_sphere4_joint_right_rear"/>
    <mechanicalReduction>1</mechanicalReduction>
    <motorTorqueConstant>1</motorTorqueConstant>
  </transmission>
  <transmission name="omniwheel_trans_left_front" type="pr2_mechanism_model/SimpleTransmission">
    <actuator name="omniwheel_motor_left_front"/>
    <joint name="omni_sphere5_joint_left_front"/>
    <mechanicalReduction>1</mechanicalReduction>
    <motorTorqueConstant>1</motorTorqueConstant>
  </transmission>
  <transmission name="omniwheel_trans_right_front" type="pr2_mechanism_model/SimpleTransmission">
    <actuator name="omniwheel_motor_right_front"/>
    <joint name="omni_sphere5_joint_right_front"/>
    <mechanicalReduction>1</mechanicalReduction>
    <motorTorqueConstant>1</motorTorqueConstant>
  </transmission>
  <transmission name="omniwheel_trans_left_rear" type="pr2_mechanism_model/SimpleTransmission">
    <actuator name="omniwheel_motor_left_rear"/>
    <joint name="omni_sphere5_joint_left_rear"/>
    <mechanicalReduction>1</mechanicalReduction>
    <motorTorqueConstant>1</motorTorqueConstant>
  </transmission>
  <transmission name="omniwheel_trans_right_rear" type="pr2_mechanism_model/SimpleTransmission">
    <actuator name="omniwheel_motor_right_rear"/>
    <joint name="omni_sphere5_joint_right_rear"/>
    <mechanicalReduction>1</mechanicalReduction>
    <motorTorqueConstant>1</motorTorqueConstant>
  </transmission>
  <transmission name="omniwheel_trans_left_front" type="pr2_mechanism_model/SimpleTransmission">
    <actuator name="omniwheel_motor_left_front"/>
    <joint name="omni_sphere6_joint_left_front"/>
    <mechanicalReduction>1</mechanicalReduction>
    <motorTorqueConstant>1</motorTorqueConstant>
  </transmission>
  <transmission name="omniwheel_trans_right_front" type="pr2_mechanism_model/SimpleTransmission">
    <actuator name="omniwheel_motor_right_front"/>
    <joint name="omni_sphere6_joint_right_front"/>
    <mechanicalReduction>1</mechanicalReduction>
    <motorTorqueConstant>1</motorTorqueConstant>
  </transmission>
  <transmission name="omniwheel_trans_left_rear" type="pr2_mechanism_model/SimpleTransmission">
    <actuator name="omniwheel_motor_left_rear"/>
    <joint name="omni_sphere6_joint_left_rear"/>
    <mechanicalReduction>1</mechanicalReduction>
    <motorTorqueConstant>1</motorTorqueConstant>
  </transmission>
  <transmission name="omniwheel_trans_right_rear" type="pr2_mechanism_model/SimpleTransmission">
    <actuator name="omniwheel_motor_right_rear"/>
    <joint name="omni_sphere6_joint_right_rear"/>
    <mechanicalReduction>1</mechanicalReduction>
    <motorTorqueConstant>1</motorTorqueConstant>
  </transmission>
  <transmission name="omniwheel_trans_left_front" type="pr2_mechanism_model/SimpleTransmission">
    <actuator name="omniwheel_motor_left_front"/>
    <joint name="omni_sphere7_joint_left_front"/>
    <mechanicalReduction>1</mechanicalReduction>
    <motorTorqueConstant>1</motorTorqueConstant>
  </transmission>
  <transmission name="omniwheel_trans_right_front" type="pr2_mechanism_model/SimpleTransmission">
    <actuator name="omniwheel_motor_right_front"/>
    <joint name="omni_sphere7_joint_right_front"/>
    <mechanicalReduction>1</mechanicalReduction>
    <motorTorqueConstant>1</motorTorqueConstant>
  </transmission>
  <transmission name="omniwheel_trans_left_rear" type="pr2_mechanism_model/SimpleTransmission">
    <actuator name="omniwheel_motor_left_rear"/>
    <joint name="omni_sphere7_joint_left_rear"/>
    <mechanicalReduction>1</mechanicalReduction>
    <motorTorqueConstant>1</motorTorqueConstant>
  </transmission>
  <transmission name="omniwheel_trans_right_rear" type="pr2_mechanism_model/SimpleTransmission">
    <actuator name="omniwheel_motor_right_rear"/>
    <joint name="omni_sphere7_joint_right_rear"/>
    <mechanicalReduction>1</mechanicalReduction>
    <motorTorqueConstant>1</motorTorqueConstant>
  </transmission>
  <transmission name="omniwheel_trans_left_front" type="pr2_mechanism_model/SimpleTransmission">
    <actuator name="omniwheel_motor_left_front"/>
    <joint name="omni_sphere8_joint_left_front"/>
    <mechanicalReduction>1</mechanicalReduction>
    <motorTorqueConstant>1</motorTorqueConstant>
  </transmission>
  <transmission name="omniwheel_trans_right_front" type="pr2_mechanism_model/SimpleTransmission">
    <actuator name="omniwheel_motor_right_front"/>
    <joint name="omni_sphere8_joint_right_front"/>
    <mechanicalReduction>1</mechanicalReduction>
    <motorTorqueConstant>1</motorTorqueConstant>
  </transmission>
  <transmission name="omniwheel_trans_left_rear" type="pr2_mechanism_model/SimpleTransmission">
    <actuator name="omniwheel_motor_left_rear"/>
    <joint name="omni_sphere8_joint_left_rear"/>
    <mechanicalReduction>1</mechanicalReduction>
    <motorTorqueConstant>1</motorTorqueConstant>
  </transmission>
  <transmission name="omniwheel_trans_right_rear" type="pr2_mechanism_model/SimpleTransmission">
    <actuator name="omniwheel_motor_right_rear"/>
    <joint name="omni_sphere8_joint_right_rear"/>
    <mechanicalReduction>1</mechanicalReduction>
    <motorTorqueConstant>1</motorTorqueConstant>
  </transmission>
  <transmission name="omniwheel_trans_left_front" type="pr2_mechanism_model/SimpleTransmission">
    <actuator name="omniwheel_motor_left_front"/>
    <joint name="omni_sphere9_joint_left_front"/>
    <mechanicalReduction>1</mechanicalReduction>
    <motorTorqueConstant>1</motorTorqueConstant>
  </transmission>
  <transmission name="omniwheel_trans_right_front" type="pr2_mechanism_model/SimpleTransmission">
    <actuator name="omniwheel_motor_right_front"/>
    <joint name="omni_sphere9_joint_right_front"/>
    <mechanicalReduction>1</mechanicalReduction>
    <motorTorqueConstant>1</motorTorqueConstant>
  </transmission>
  <transmission name="omniwheel_trans_left_rear" type="pr2_mechanism_model/SimpleTransmission">
    <actuator name="omniwheel_motor_left_rear"/>
    <joint name="omni_sphere9_joint_left_rear"/>
    <mechanicalReduction>1</mechanicalReduction>
    <motorTorqueConstant>1</motorTorqueConstant>
  </transmission>
  <transmission name="omniwheel_trans_right_rear" type="pr2_mechanism_model/SimpleTransmission">
    <actuator name="omniwheel_motor_right_rear"/>
    <joint name="omni_sphere9_joint_right_rear"/>
    <mechanicalReduction>1</mechanicalReduction>
    <motorTorqueConstant>1</motorTorqueConstant>
  </transmission>
  <transmission name="omniwheel_trans_left_front" type="pr2_mechanism_model/SimpleTransmission">
    <actuator name="omniwheel_motor_left_front"/>
    <joint name="omni_sphere10_joint_left_front"/>
    <mechanicalReduction>1</mechanicalReduction>
    <motorTorqueConstant>1</motorTorqueConstant>
  </transmission>
  <transmission name="omniwheel_trans_right_front" type="pr2_mechanism_model/SimpleTransmission">
    <actuator name="omniwheel_motor_right_front"/>
    <joint name="omni_sphere10_joint_right_front"/>
    <mechanicalReduction>1</mechanicalReduction>
    <motorTorqueConstant>1</motorTorqueConstant>
  </transmission>
  <transmission name="omniwheel_trans_left_rear" type="pr2_mechanism_model/SimpleTransmission">
    <actuator name="omniwheel_motor_left_rear"/>
    <joint name="omni_sphere10_joint_left_rear"/>
    <mechanicalReduction>1</mechanicalReduction>
    <motorTorqueConstant>1</motorTorqueConstant>
  </transmission>
  <transmission name="omniwheel_trans_right_rear" type="pr2_mechanism_model/SimpleTransmission">
    <actuator name="omniwheel_motor_right_rear"/>
    <joint name="omni_sphere10_joint_right_rear"/>
    <mechanicalReduction>1</mechanicalReduction>
    <motorTorqueConstant>1</motorTorqueConstant>
  </transmission>
  <transmission name="omniwheel_trans_left_front" type="pr2_mechanism_model/SimpleTransmission">
    <actuator name="omniwheel_motor_left_front"/>
    <joint name="omni_sphere11_joint_left_front"/>
    <mechanicalReduction>1</mechanicalReduction>
    <motorTorqueConstant>1</motorTorqueConstant>
  </transmission>
  <transmission name="omniwheel_trans_right_front" type="pr2_mechanism_model/SimpleTransmission">
    <actuator name="omniwheel_motor_right_front"/>
    <joint name="omni_sphere11_joint_right_front"/>
    <mechanicalReduction>1</mechanicalReduction>
    <motorTorqueConstant>1</motorTorqueConstant>
  </transmission>
  <transmission name="omniwheel_trans_left_rear" type="pr2_mechanism_model/SimpleTransmission">
    <actuator name="omniwheel_motor_left_rear"/>
    <joint name="omni_sphere11_joint_left_rear"/>
    <mechanicalReduction>1</mechanicalReduction>
    <motorTorqueConstant>1</motorTorqueConstant>
  </transmission>
  <transmission name="omniwheel_trans_right_rear" type="pr2_mechanism_model/SimpleTransmission">
    <actuator name="omniwheel_motor_right_rear"/>
    <joint name="omni_sphere11_joint_right_rear"/>
    <mechanicalReduction>1</mechanicalReduction>
    <motorTorqueConstant>1</motorTorqueConstant>
  </transmission>
  <transmission name="omniwheel_trans_left_front" type="pr2_mechanism_model/SimpleTransmission">
    <actuator name="omniwheel_motor_left_front"/>
    <joint name="omni_sphere12_joint_left_front"/>
    <mechanicalReduction>1</mechanicalReduction>
    <motorTorqueConstant>1</motorTorqueConstant>
  </transmission>
  <transmission name="omniwheel_trans_right_front" type="pr2_mechanism_model/SimpleTransmission">
    <actuator name="omniwheel_motor_right_front"/>
    <joint name="omni_sphere12_joint_right_front"/>
    <mechanicalReduction>1</mechanicalReduction>
    <motorTorqueConstant>1</motorTorqueConstant>
  </transmission>
  <transmission name="omniwheel_trans_left_rear" type="pr2_mechanism_model/SimpleTransmission">
    <actuator name="omniwheel_motor_left_rear"/>
    <joint name="omni_sphere12_joint_left_rear"/>
    <mechanicalReduction>1</mechanicalReduction>
    <motorTorqueConstant>1</motorTorqueConstant>
  </transmission>
  <transmission name="omniwheel_trans_right_rear" type="pr2_mechanism_model/SimpleTransmission">
    <actuator name="omniwheel_motor_right_rear"/>
    <joint name="omni_sphere12_joint_right_rear"/>
    <mechanicalReduction>1</mechanicalReduction>
    <motorTorqueConstant>1</motorTorqueConstant>
  </transmission>
  <transmission name="neck_trans" type="pr2_mechanism_model/SimpleTransmission">
    <actuator name="neck_motor"/>
    <joint name="neck_pan_joint"/>
    <mechanicalReduction>1</mechanicalReduction>
    <motorTorqueConstant>1</motorTorqueConstant>
  </transmission>
  <transmission name="head_trans" type="pr2_mechanism_model/SimpleTransmission">
    <actuator name="head_motor"/>
    <joint name="neck_tilt_joint"/>
    <mechanicalReduction>1</mechanicalReduction>
    <motorTorqueConstant>1</motorTorqueConstant>
  </transmission>
</robot>
